Workbook

Sheet Dashboard
A1: BUDGET PLANNER - VISUAL DASHBOARD
A3: YOUR MONTHLY OVERVIEW
A4: Total Monthly Income | B4: ₹ | C4: =SUM('Monthly Budget'!D5:D7) -> 0
A6: INCOME BREAKDOWN
A7: Salary/Primary Income | B7: ₹ | C7: ='Monthly Budget'!D5 -> 0
A8: Side Income/Freelance | B8: ₹ | C8: ='Monthly Budget'!D6 -> 0
A9: Other Income | B9: ₹ | C9: ='Monthly Budget'!D7 -> 0
A11: EXPENSE SUMMARY (50/30/20 Rule)
A12: Category | B12: Amount (₹) | C12: % of Income | D12: Target % | E12: Status
A13: NEEDS (Essential) | B13: ='Monthly Budget'!D24 -> 0 | C13: ='Monthly Budget'!D57 -> 0 | D13: 50% | E13: =IF(D13<=0.50,"✓ On Target","⚠ Over") -> 0
A14: WANTS (Discretionary) | B14: ='Monthly Budget'!D39 -> 0 | C14: ='Monthly Budget'!D58 -> 0 | D14: 30% | E14: =IF(D14<=0.30,"✓ On Target","⚠ Over") -> 0
A15: SAVINGS (Investments) | B15: ='Monthly Budget'!D49 -> 0 | C15: ='Monthly Budget'!D59 -> 0 | D15: 20% | E15: =IF(D15>=0.20,"✓ On Track","⚠ Below Target") -> 0
A17: QUICK INSIGHTS
A18: Total Expenses | B18: ₹ | C18: =D13+D14 -> 0
A19: Total Savings Allocated | B19: ₹ | C19: =D15 -> 0
A20: Remaining Unallocated | B20: ₹ | C20: =D4-D18-D19 -> 0
A22: BUDGET HEALTH CHECK
A23: Are you within 50% for Needs? | C23: =IF(D13<=0.50,"✓ YES","✗ NO") -> 0
A24: Are you within 30% for Wants? | C24: =IF(D14<=0.30,"✓ YES","✗ NO") -> 0
A25: Are you saving 20%? | C25: =IF(D15>=0.20,"✓ YES","✗ NO") -> 0
A26: Overall Balance | C26: =IF(AND(D13<=0.50,D14<=0.30,D15>=0.20),"✓ BALANCED","⚠ NEEDS ADJUSTMENT") -> 0

Sheet Monthly Budget
A1: MONTHLY BUDGET PLANNER - 50/30/20 RULE
A3: MONTHLY INCOME
A4: Income Source | B4: Description | C4: Currency | D4: Amount | E4: Notes
A5: Salary/Primary Income | B5: Regular employment income | C5: ₹ | D5: 0 | E5: Enter your main salary
A6: Side Income/Freelance | B6: Projects, freelance work, gig income | C6: ₹ | D6: 0 | E6: Optional: freelance earnings
A7: Other Income | B7: Bonuses, allowances, rental income | C7: ₹ | D7: 0 | E7: One-time or recurring
A8: TOTAL MONTHLY INCOME | C8: ₹ | D8: =SUM(D5:D7) -> 0
A11: NEEDS - ESSENTIAL EXPENSES (50% TARGET)
A12: Category | B12: Description | C12: Currency | D12: Amount | E12: Category Type
A13: Rent/Mortgage | B13: Monthly rent or mortgage payment | C13: ₹ | D13: 0 | E13: Needs
A14: Utilities (Electricity, Water, Gas) | B14: Monthly utility bills | C14: ₹ | D14: 0 | E14: Needs
A15: Groceries & Food (Home) | B15: Weekly/monthly grocery shopping | C15: ₹ | D15: 0 | E15: Needs
A16: Transportation (Fuel, Public Transit) | B16: Daily commute costs | C16: ₹ | D16: 0 | E16: Needs
A17: Insurance (Health, Life, Vehicle) | B17: All insurance premiums | C17: ₹ | D17: 0 | E17: Needs
A18: Phone & Internet Bill | B18: Mobile and broadband bills | C18: ₹ | D18: 0 | E18: Needs
A19: Medical Expenses | B19: Doctor visits, medicines, tests | C19: ₹ | D19: 0 | E19: Needs
A20: Loan EMI (if any) | B20: Car loan, personal loan payments | C20: ₹ | D20: 0 | E20: Needs
A21: Education Fees | B21: School/college/course fees | C21: ₹ | D21: 0 | E21: Needs
A22: Childcare/Dependent Support | B22: Child care, elderly support | C22: ₹ | D22: 0 | E22: Needs
A23: TOTAL NEEDS | C23: ₹ | D23: =SUM(D14:D23) -> 0 | E23: 50% Target
A25: WANTS - DISCRETIONARY SPENDING (30% TARGET)
A26: Category | B26: Description | C26: Currency | D26: Amount | E26: Category Type
A27: Dining Out & Entertainment | B27: Restaurants, cafes, casual dining | C27: ₹ | D27: 0 | E27: Wants
A28: Movies & Events | B28: Cinema, concerts, shows | C28: ₹ | D28: 0 | E28: Wants
A29: Subscriptions (Netflix, Apps, etc.) | B29: OTT, music, app subscriptions | C29: ₹ | D29: 0 | E29: Wants
A30: Shopping (Clothes, Accessories) | B30: Apparel and accessories | C30: ₹ | D30: 0 | E30: Wants
A31: Hobbies & Sports | B31: Sports equipment, hobby expenses | C31: ₹ | D31: 0 | E31: Wants
A32: Travel & Vacation | B32: Holiday, getaways | C32: ₹ | D32: 0 | E32: Wants
A33: Gifts & Celebrations | B33: Birthdays, festivals, occasions | C33: ₹ | D33: 0 | E33: Wants
A34: Personal Care (Salon, Gym) | B34: Salon, gym, spa, beauty | C34: ₹ | D34: 0 | E34: Wants
A35: Gadgets & Electronics | B35: Phones, laptops, accessories | C35: ₹ | D35: 0 | E35: Wants
A36: Books, Courses & Learning | B36: Books, online courses, workshops | C36: ₹ | D36: 0 | E36: Wants
A37: Pet Care & Supplies | B37: Pet food, vet, grooming | C37: ₹ | D37: 0 | E37: Wants
A38: Premium/Organic Food | B38: Imported, organic, premium items | C38: ₹ | D38: 0 | E38: Wants
A39: TOTAL WANTS | C39: ₹ | D39: =SUM(D27:D38) -> 0 | E39: 30% Target
A41: SAVINGS & INVESTMENTS (20% TARGET)
A42: Category | B42: Description | C42: Currency | D42: Amount | E42: Category Type
A43: Emergency Fund | B43: Liquid savings for emergencies | C43: ₹ | D43: 0 | E43: Savings
A44: Fixed Deposits/Bonds | B44: Bank deposits, bonds | C44: ₹ | D44: 0 | E44: Savings
A45: Mutual Funds (SIP) | B45: Systematic investment plan | C45: ₹ | D45: 0 | E45: Savings
...

Sheet Category Guide
A1: BUDGET CATEGORY REFERENCE & SPENDING GUIDE
A3: HOW TO USE THIS BUDGET PLANNER:
A4: 1. INCOME TAB | B4: Enter your monthly income sources in the Monthly Budget sheet
A5: 2. EXPENSES TAB | B5: Fill in your expected expenses for each category
A6: 3. AUTOMATIC ANALYSIS | B6: The Dashboard and Monthly Budget sheets auto-calculate your 50/30/20 analysis
A7: 4. REVIEW & ADJUST | B7: Compare actual % with targets. Adjust spending as needed
A9: NEEDS (Essential Expenses - 50% Target)
A10: Category | B10: Includes | C10: Monthly Range (Example) | D10: Tips
A11: Rent/Housing | B11: Rent, mortgage, maintenance, property tax | C11: ₹10,000 - ₹50,000 | D11: Usually your largest expense
A12: Utilities | B12: Electricity, water, gas, internet, landline | C12: ₹2,000 - ₹8,000 | D12: Track usage to reduce bills
A13: Groceries | B13: Food, spices, household essentials, cleaning | C13: ₹3,000 - ₹10,000 | D13: Plan meals, buy bulk smartly
A14: Transportation | B14: Fuel, public transit, car maintenance, parking | C14: ₹2,000 - ₹15,000 | D14: Calculate commute costs
A15: Insurance | B15: Health, life, vehicle, property insurance | C15: ₹2,000 - ₹12,000 | D15: Essential protection layer
A16: Phone/Internet | B16: Mobile bills, broadband, landline | C16: ₹500 - ₹3,000 | D16: Shop for better plans
A17: Medical | B17: Doctor visits, medicines, health checkups | C17: ₹1,000 - ₹5,000 | D17: Preventive care saves costs
A18: Loan EMI | B18: Car loan, personal loan, student loan | C18: ₹5,000 - ₹50,000 | D18: Fixed obligation
A19: Education | B19: School, college, training fees | C19: ₹2,000 - ₹20,000 | D19: Essential for growth
A20: Dependents | B20: Childcare, elderly care, family support | C20: ₹3,000 - ₹25,000 | D20: Calculate all care costs
A22: WANTS (Discretionary Spending - 30% Target)
A23: Category | B23: Includes | C23: Monthly Range (Example) | D23: Tips
A24: Dining Out | B24: Restaurants, cafes, fast food, delivery | C24: ₹2,000 - ₹10,000 | D24: Set limits, track spending
A25: Entertainment | B25: Movies, concerts, shows, gaming | C25: ₹1,000 - ₹5,000 | D25: Plan outings in advance
A26: Subscriptions | B26: Netflix, Spotify, apps, memberships | C26: ₹500 - ₹3,000 | D26: Cancel unused subscriptions
A27: Shopping | B27: Clothes, shoes, accessories, fashion | C27: ₹2,000 - ₹15,000 | D27: Use wish list, wait before buying
A28: Hobbies | B28: Sports, photography, collections, crafts | C28: ₹1,000 - ₹10,000 | D28: Budget per hobby
A29: Travel/Vacation | B29: Holidays, weekend trips, tours | C29: ₹5,000 - ₹30,000 | D29: Plan quarterly or annual
A30: Gifts | B30: Birthdays, festivals, celebrations, presents | C30: ₹2,000 - ₹10,000 | D30: Set occasion budgets
A31: Personal Care | B31: Salon, gym, spa, beauty treatments | C31: ₹2,000 - ₹10,000 | D31: Monthly wellness spending
A32: Gadgets | B32: Phones, laptops, tech accessories | C32: ₹0 - ₹50,000 | D32: One-time purchases
A33: Learning | B33: Books, courses, workshops, skills | C33: ₹500 - ₹5,000 | D33: Invest in yourself
A34: Pet Care | B34: Pet food, vet, toys, grooming | C34: ₹1,000 - ₹8,000 | D34: Budget pet healthcare
A35: Premium Food | B35: Organic, imported, premium groceries | C35: ₹1,000 - ₹8,000 | D35: Quality vs. bulk trade-off
A37: SAVINGS & INVESTMENTS (20% Target)
A38: Category | B38: Purpose | C38: Time Horizon | D38: Risk Level | E38: Tips
A39: Emergency Fund | B39: Backup for unexpected expenses (6 months salary) | C39: Always accessible | D39: Very Low | E39: Keep in savings account
A40: Fixed Deposits | B40: Guaranteed returns, safe savings | C40: 1-3 years | D40: Very Low | E40: Shop for best rates
A41: Mutual Funds (SIP) | B41: Regular investments, market growth | C41: 3-7 years | D41: Low-Medium | E41: Automate via SIP
A42: Stocks | B42: Direct equity, high growth potential | C42: 5+ years | D42: High | E42: Research before investing
A43: NPS/Retirement | B43: Long-term retirement corpus | C43: 20-30 years | D43: Low-Medium | E43: Tax benefits available
A44: Gold/Silver | B44: Inflation hedge, safe investment | C44: 5-10 years | D44: Low | E44: Buy during dips
...

Sheet Monthly Tracker
A1: DAILY EXPENSE TRACKER - Track actual spending daily
A3: Instructions: Enter each transaction as you spend. System auto-calculates totals.
A5: DAILY TRANSACTION LOG
A6: Date (DD-MM-YYYY) | B6: Category Type | C6: Category Name | D6: Amount (₹) | E6: Notes/Description
A7: 2026-01-02 | B7: Needs | C7: Groceries | D7: 0
A25: MONTHLY SUMMARY BY CATEGORY
A26: Category Type | B26: Total Amount (₹) | C26: % of Income | D26: Budget Target % | E26: Status
A27: Needs | B27: 0 | C27: 0% | D27: 50%
A28: Wants | B28: 0 | C28: 0% | D28: 30%
A29: Savings | B29: 0 | C29: 0% | D29: 20%
