Workbook

Sheet Dashboard
A1: DEBT FREEDOM TRACKER - VISUAL DASHBOARD
A3: YOUR DEBT OVERVIEW
A4: Total Debt Amount | B4: ₹ | C4: =SUM('Debt Inventory'!D5:D14) -> 0
A5: Total Monthly Payment | B5: ₹ | C5: =SUM('Payment Schedule'!D6:D35) -> 0
A6: Total Interest Paid (Lifetime) | B6: ₹ | C6: =SUM('Payment Schedule'!E6:E35) -> 0
A8: PAYOFF STRATEGY COMPARISON
A9: Strategy | B9: Monthly Payment | C9: Total Interest | D9: Time to Payoff | E9: Recommended For
A10: Snowball Method | B10: =IF('Debt List'!D3=0,"Customize","See Snowball") -> 0 | C10: =IF('Debt List'!D3=0,"--","Optimized") -> 0 | D10: =IF('Debt List'!D3=0,"--","Faster motivation") -> 0 | E10: Psychological wins
A11: Avalanche Method | B11: =IF('Debt List'!D3=0,"Customize","See Avalanche") -> 0 | C11: =IF('Debt List'!D3=0,"--","Optimized") -> 0 | D11: =IF('Debt List'!D3=0,"--","Maximum savings") -> 0 | E11: Interest minimization
A13: DEBT-FREE DATE PROJECTION
A14: Using Snowball Strategy | B14: Date | C14: =IF('Debt List'!D3=0,"Enter debts","Calculate") -> 0
A15: Using Avalanche Strategy | B15: Date | C15: =IF('Debt List'!D3=0,"Enter debts","Calculate") -> 0
A16: Faster Method Advantage | B16: Months Saved | C16: =IF('Debt List'!D3=0,0,"0-36 months typical") -> 0
A18: INTEREST SAVINGS TRACKER
A19: Interest Paid vs Saved | B19: Amount (₹) | C19: Percentage | D19: Impact
A20: Interest with Snowball | B20: =SUM('Snowball'!E:E) -> 0 | C20: 100% | D20: Balanced approach
A21: Interest with Avalanche | B21: =SUM('Avalanche'!E:E) -> 0 | C21: 100% | D21: Maximum savings
A22: Potential Savings | B22: =(SUM('Snowball'!E:E)-SUM('Avalanche'!E:E)) -> 0 | C22: =(((SUM('Snowball'!E:E)-SUM('Avalanche'!E:E))/SUM('Snowball'!E:E))*100)% -> 0 | D22: Avalanche advantage
A24: MILESTONES & PROGRESS
A25: Milestone | B25: Target Date | C25: Amount Remaining | D25: Status
A26: 25% Debt Cleared | B26: TBD | C26: =('Dashboard'!B3*0.75) -> 0 | D26: Track progress
A27: 50% Debt Cleared (Halfway!) | B27: TBD | C27: =('Dashboard'!B3*0.50) -> 0 | D27: Motivational point
A28: 75% Debt Cleared | B28: TBD | C28: =('Dashboard'!B3*0.25) -> 0 | D28: Almost there!
A29: 100% DEBT FREE! | B29: TBD | C29: ₹0 | D29: FREEDOM!
A31: QUICK INSIGHTS
A32: Average Interest Rate | B32: =AVERAGE('Debt Inventory'!C5:C14)% -> 0 | C32: Across all debts
A33: Highest Interest Debt | B33: Max: 45% | C33: Priority for avalanche
A34: Monthly Extra Payment Capacity | B34: ₹ | C34: 0 | D34: Add to accelerate payoff
A35: Years to Debt Freedom (Current pace) | B35: =IF('Dashboard'!B3=0,0,('Dashboard'!B3)/('Dashboard'!B4*12))% -> 0 | C35: Estimate

Sheet Debt Inventory
A1: DEBT INVENTORY - LIST ALL YOUR DEBTS
A3: Add all debts below. The system will auto-calculate payoff strategies.
A5: Debt Details
A6: Debt Name | B6: Type | C6: Interest Rate (%) | D6: Current Balance (₹) | E6: Min. Monthly Payment (₹)
A7: Credit Card 1 | B7: Credit Card | C7: 0 | D7: 0 | E7: 0
A8: Credit Card 2 | B8: Credit Card | C8: 0 | D8: 0 | E8: 0
A9: Personal Loan 1 | B9: Personal Loan | C9: 0 | D9: 0 | E9: 0
A10: Auto Loan | B10: Vehicle Loan | C10: 0 | D10: 0 | E10: 0
A11: Education Loan | B11: Student Loan | C11: 0 | D11: 0 | E11: 0
A12: Home Loan | B12: Mortgage | C12: 0 | D12: 0 | E12: 0
A13: Medical Debt | B13: Other | C13: 0 | D13: 0 | E13: 0
A14: Family Loan | B14: Personal | C14: 0 | D14: 0 | E14: 0
A15: Business Loan | B15: Business | C15: 0 | D15: 0 | E15: 0
A16: Other Debt | B16: Other | C16: 0 | D16: 0 | E16: 0
A18: SUMMARY STATISTICS
A19: Total Debt | B19: ₹ | C19: =SUM(D5:D14) -> 0
A20: Total Monthly Minimum Payment | B20: ₹ | C20: =SUM(E5:E14) -> 0
A21: Average Interest Rate | C21: =AVERAGE(C5:C14)% -> 0
A22: Highest Interest Debt | C22: =MAX(C5:C14)% -> 0
A23: Lowest Interest Debt | C23: =MIN(C5:C14)% -> 0
A24: Number of Debts | C24: =COUNTA(A5:A14) -> 0

Sheet Snowball
A1: SNOWBALL METHOD - PSYCHOLOGICAL APPROACH
A3: Snowball Strategy: Pay smallest balance first (regardless of interest)
A4: Benefit: Quick wins boost motivation and momentum
A5: Approach: Minimum payment on all, extra towards smallest debt
A7: SNOWBALL PAYOFF SCHEDULE
A8: Month | B8: Debt Priority (by balance) | C8: Payment (₹) | D8: Interest (₹) | E8: Principal (₹) | F8: Remaining (₹)
A9: 1 | B9: Target: Smallest balance debt | C9: 0 | D9: 0 | E9: 0 | F9: 0
A10: 2 | B10: Continue smallest | C10: 0 | D10: 0 | E10: 0 | F10: 0
A11: 3 | B11: Continue smallest | C11: 0 | D11: 0 | E11: 0 | F11: 0
A12: 4 | B12: Continue smallest | C12: 0 | D12: 0 | E12: 0 | F12: 0
A13: 5 | B13: Continue smallest | C13: 0 | D13: 0 | E13: 0 | F13: 0
A14: 6 | B14: Continue smallest | C14: 0 | D14: 0 | E14: 0 | F14: 0
A15: 7 | B15: Move to next smallest | C15: 0 | D15: 0 | E15: 0 | F15: 0
A16: 8 | B16: Next debt (freed up payment) | C16: 0 | D16: 0 | E16: 0 | F16: 0
A17: 9 | B17: Continue snowball | C17: 0 | D17: 0 | E17: 0 | F17: 0
A18: 10 | B18: Building momentum | C18: 0 | D18: 0 | E18: 0 | F18: 0
A19: 11 | B19: Acceleration phase | C19: 0 | D19: 0 | E19: 0 | F19: 0
A20: 12 | B20: End of Year 1 | C20: 0 | D20: 0 | E20: 0 | F20: 0
A22: YEAR 1 SUMMARY
A23: Total Paid | B23: ₹ | C23: =SUM(C8:C19) -> 0
A24: Interest Paid | B24: ₹ | C24: =SUM(D8:D19) -> 0
A25: Principal Paid | B25: ₹ | C25: =SUM(E8:E19) -> 0
A26: Debt Eliminated | C26: =COUNTIF(F8:F19,0) -> 0 | D26: Debts fully paid off
A27: Remaining Debt | B27: ₹ | C27: =SUM(F8:F19) -> 0
A29: SNOWBALL PAYOFF ORDER (by current balance - smallest first)
A30: Priority | B30: Debt Name | C30: Current Balance | D30: Interest Rate | E30: Payoff Time (approx.)
A31: 1 | B31: =INDEX('Debt Inventory'!A5:A14,MATCH(MIN('Debt Inventory'!D5:D14),'Debt Inventory'!D5:D14,0)) -> 0 | C31: =MIN('Debt Inventory'!D5:D14) -> 0 | D31: =INDEX('Debt Inventory'!C5:C14,MATCH(MIN('Debt Inventory'!D5:D14),'Debt Inventory'!D5:D14,0)) -> 0 | E31: Months
A32: 2 | B32: Next smallest | C32: Balance | D32: Rate | E32: Months
A33: 3 | B33: Next | C33: Balance | D33: Rate | E33: Months
A34: 4 | B34: Next | C34: Balance | D34: Rate | E34: Months
A35: 5 | B35: Next | C35: Balance | D35: Rate | E35: Months
A37: SNOWBALL ADVANTAGES
A38: ✓ Psychological Boost | B38: Quick wins with small debts eliminated first
A39: ✓ Motivation Builder | B39: Visible progress keeps you engaged
A40: ✓ Debt-Free Milestones | B40: Multiple celebration points as you go
A41: ✓ Simpler to Execute | B41: Just pay smallest balance, ignore interest rates
A42: ✓ Better for Behavioral Change | B42: Success breeds more commitment
A44: SNOWBALL DISADVANTAGES
A45: ✗ Higher Total Interest | B45: Ignores high-interest debts that hurt more
A46: ✗ Longer Payoff Period | B46: May take months/years longer than avalanche
...

Sheet Avalanche
A1: AVALANCHE METHOD - MATHEMATICAL APPROACH
A3: Avalanche Strategy: Pay highest interest rate first (regardless of balance)
A4: Benefit: Saves the most interest money over time
A5: Approach: Minimum payment on all, extra towards highest interest debt
A7: AVALANCHE PAYOFF SCHEDULE
A8: Month | B8: Debt Priority (by interest rate) | C8: Payment (₹) | D8: Interest (₹) | E8: Principal (₹) | F8: Remaining (₹)
A9: 1 | B9: Target: Highest interest debt | C9: 0 | D9: 0 | E9: 0 | F9: 0
A10: 2 | B10: Continue highest rate | C10: 0 | D10: 0 | E10: 0 | F10: 0
A11: 3 | B11: Continue highest rate | C11: 0 | D11: 0 | E11: 0 | F11: 0
A12: 4 | B12: Continue highest rate | C12: 0 | D12: 0 | E12: 0 | F12: 0
A13: 5 | B13: Continue highest rate | C13: 0 | D13: 0 | E13: 0 | F13: 0
A14: 6 | B14: Continue highest rate | C14: 0 | D14: 0 | E14: 0 | F14: 0
A15: 7 | B15: Move to next highest | C15: 0 | D15: 0 | E15: 0 | F15: 0
A16: 8 | B16: Next debt (freed up payment) | C16: 0 | D16: 0 | E16: 0 | F16: 0
A17: 9 | B17: Continue avalanche | C17: 0 | D17: 0 | E17: 0 | F17: 0
A18: 10 | B18: Accelerating payoff | C18: 0 | D18: 0 | E18: 0 | F18: 0
A19: 11 | B19: Interest costs dropping | C19: 0 | D19: 0 | E19: 0 | F19: 0
A20: 12 | B20: End of Year 1 | C20: 0 | D20: 0 | E20: 0 | F20: 0
A22: YEAR 1 SUMMARY
A23: Total Paid | B23: ₹ | C23: =SUM(C8:C19) -> 0
A24: Interest Paid | B24: ₹ | C24: =SUM(D8:D19) -> 0
A25: Principal Paid | B25: ₹ | C25: =SUM(E8:E19) -> 0
A26: Debt Eliminated | C26: =COUNTIF(F8:F19,0) -> 0 | D26: Debts fully paid off
A27: Remaining Debt | B27: ₹ | C27: =SUM(F8:F19) -> 0
A29: AVALANCHE PAYOFF ORDER (by interest rate - highest first)
A30: Priority | B30: Debt Name | C30: Current Balance | D30: Interest Rate | E30: Payoff Time (approx.)
A31: 1 | B31: =INDEX('Debt Inventory'!A5:A14,MATCH(MAX('Debt Inventory'!C5:C14),'Debt Inventory'!C5:C14,0)) -> 0 | C31: =INDEX('Debt Inventory'!D5:D14,MATCH(MAX('Debt Inventory'!C5:C14),'Debt Inventory'!C5:C14,0)) -> 0 | D31: =MAX('Debt Inventory'!C5:C14)% -> 0 | E31: Months
A32: 2 | B32: Next highest | C32: Balance | D32: Rate | E32: Months
A33: 3 | B33: Next | C33: Balance | D33: Rate | E33: Months
A34: 4 | B34: Next | C34: Balance | D34: Rate | E34: Months
A35: 5 | B35: Next | C35: Balance | D35: Rate | E35: Months
A37: AVALANCHE ADVANTAGES
A38: ✓ Saves Maximum Interest | B38: Target highest-cost debts first
A39: ✓ Mathematically Optimal | B39: Most efficient path to debt freedom
A40: ✓ Fastest Total Payoff | B40: Reduced compound interest over time
A41: ✓ Cost-Efficient | B41: Saves thousands in interest
A42: ✓ Recommended by Finance Experts | B42: Endorsed by financial advisors
A44: AVALANCHE DISADVANTAGES
A45: ✗ Slower Early Wins | B45: High interest debts take longer
A46: ✗ Requires Discipline | B46: No quick small debt victories
...

Sheet Payment Schedule
A1: DETAILED PAYMENT TRACKER & AMORTIZATION SCHEDULE
A3: Instructions: Select your preferred strategy (Snowball/Avalanche) above. Enter extra monthly payment capacity.
A5: MONTHLY PAYMENT SCHEDULE (12-Month View)
A6: Month | B6: Date | C6: Total Payment (₹) | D6: Interest (₹) | E6: Principal (₹) | F6: Total Remaining Debt (₹)
A7: 1 | B7: 2026-01 | C7: 0 | D7: 0 | E7: 0 | F7: =SUM('Debt Inventory'!D5:D14) -> 0
A8: 2 | B8: 2026-02 | C8: 0 | D8: 0 | E8: 0 | F8: 0
A9: 3 | B9: 2026-03 | C9: 0 | D9: 0 | E9: 0 | F9: 0
A10: 4 | B10: 2026-04 | C10: 0 | D10: 0 | E10: 0 | F10: 0
A11: 5 | B11: 2026-05 | C11: 0 | D11: 0 | E11: 0 | F11: 0
A12: 6 | B12: 2026-06 | C12: 0 | D12: 0 | E12: 0 | F12: 0
A13: 7 | B13: 2026-07 | C13: 0 | D13: 0 | E13: 0 | F13: 0
A14: 8 | B14: 2026-08 | C14: 0 | D14: 0 | E14: 0 | F14: 0
A15: 9 | B15: 2026-09 | C15: 0 | D15: 0 | E15: 0 | F15: 0
A16: 10 | B16: 2026-10 | C16: 0 | D16: 0 | E16: 0 | F16: 0
A17: 11 | B17: 2026-11 | C17: 0 | D17: 0 | E17: 0 | F17: 0
A18: 12 | B18: 2026-12 | C18: 0 | D18: 0 | E18: 0 | F18: 0
A20: ANNUAL SUMMARY
A21: Year | B21: Total Paid (₹) | C21: Interest Paid (₹) | D21: Principal Paid (₹) | E21: Debt Remaining (₹)
A22: Year 1 | B22: =SUM(C8:C19) -> 0 | C22: =SUM(D8:D19) -> 0 | D22: =SUM(E8:E19) -> 0 | E22: =SUM(F8:F19) -> 0
A23: Year 2 | B23: 0 | C23: 0 | D23: 0 | E23: 0
A24: Year 3 | B24: 0 | C24: 0 | D24: 0 | E24: 0
A25: Year 4 | B25: 0 | C25: 0 | D25: 0 | E25: 0
A26: Year 5 | B26: 0 | C26: 0 | D26: 0 | E26: 0
A28: CUMULATIVE STATISTICS
A29: Total Paid to Date | B29: ₹ | C29: =SUM(C8:C19) -> 0
A30: Total Interest Paid | B30: ₹ | C30: =SUM(D8:D19) -> 0
A31: Total Principal Paid | B31: ₹ | C31: =SUM(E8:E19) -> 0
A32: Remaining Debt | B32: ₹ | C32: =SUM(F8:F19) -> 0
A33: Progress % | C33: =(SUM(E8:E19)/(SUM(E8:E19)+SUM(F8:F19)))*100% -> 0 | D33: How much paid off
A35: INDIVIDUAL DEBT TRACKER
A36: Debt Name | B36: Original Balance | C36: Current Balance | D36: Interest Rate | E36: Monthly Payment
A37: Credit Card 1 | B37: =D5 -> 0 | C37: =D5 -> 0 | D37: =C5% -> 0 | E37: =E5 -> 0
A38: Credit Card 2 | B38: =D6 -> 0 | C38: =D6 -> 0 | D38: =C6% -> 0 | E38: =E6 -> 0
A39: Personal Loan | B39: =D7 -> 0 | C39: =D7 -> 0 | D39: =C7% -> 0 | E39: =E7 -> 0
A40: Auto Loan | B40: =D8 -> 0 | C40: =D8 -> 0 | D40: =C8% -> 0 | E40: =E8 -> 0
A41: Education Loan | B41: =D9 -> 0 | C41: =D9 -> 0 | D41: =C9% -> 0 | E41: =E9 -> 0
A42: Home Loan | B42: =D10 -> 0 | C42: =D10 -> 0 | D42: =C10% -> 0 | E42: =E10 -> 0
A43: Medical Debt | B43: =D11 -> 0 | C43: =D11 -> 0 | D43: =C11% -> 0 | E43: =E11 -> 0
A44: Family Loan | B44: =D12 -> 0 | C44: =D12 -> 0 | D44: =C12% -> 0 | E44: =E12 -> 0
A45: Business Loan | B45: =D13 -> 0 | C45: =D13 -> 0 | D45: =C13% -> 0 | E45: =E13 -> 0
...

Sheet Interest Tracker
A1: INTEREST ANALYSIS & SAVINGS CALCULATOR
A3: Understand how much interest you pay and how to minimize it.
A5: YOUR INTEREST BREAKDOWN
A6: Debt Type | B6: Balance (₹) | C6: Interest Rate | D6: Monthly Interest (₹) | E6: Annual Interest (₹) | F6: % of Total Interest
A7: Credit Card 1 | B7: =D5 -> 0 | C7: =C5% -> 0 | D7: =(D5*C5/12/100) -> 0 | E7: =(D5*C5/100) -> 0 | F7: =(D5*C5/SUM(D5:D14*C5:C14)*100)% -> 0
A8: Credit Card 2 | B8: =D6 -> 0 | C8: =C6% -> 0 | D8: =(D6*C6/12/100) -> 0 | E8: =(D6*C6/100) -> 0 | F8: =(D6*C6/SUM(D5:D14*C5:C14)*100)% -> 0
A9: Personal Loan | B9: =D7 -> 0 | C9: =C7% -> 0 | D9: =(D7*C7/12/100) -> 0 | E9: =(D7*C7/100) -> 0 | F9: =(D7*C7/SUM(D5:D14*C5:C14)*100)% -> 0
A10: Auto Loan | B10: =D8 -> 0 | C10: =C8% -> 0 | D10: =(D8*C8/12/100) -> 0 | E10: =(D8*C8/100) -> 0 | F10: =(D8*C8/SUM(D5:D14*C5:C14)*100)% -> 0
A11: Education Loan | B11: =D9 -> 0 | C11: =C9% -> 0 | D11: =(D9*C9/12/100) -> 0 | E11: =(D9*C9/100) -> 0 | F11: =(D9*C9/SUM(D5:D14*C5:C14)*100)% -> 0
A12: Home Loan | B12: =D10 -> 0 | C12: =C10% -> 0 | D12: =(D10*C10/12/100) -> 0 | E12: =(D10*C10/100) -> 0 | F12: =(D10*C10/SUM(D5:D14*C5:C14)*100)% -> 0
A13: Medical Debt | B13: =D11 -> 0 | C13: =C11% -> 0 | D13: =(D11*C11/12/100) -> 0 | E13: =(D11*C11/100) -> 0 | F13: =(D11*C11/SUM(D5:D14*C5:C14)*100)% -> 0
A14: Family Loan | B14: =D12 -> 0 | C14: =C12% -> 0 | D14: =(D12*C12/12/100) -> 0 | E14: =(D12*C12/100) -> 0 | F14: =(D12*C12/SUM(D5:D14*C5:C14)*100)% -> 0
A15: Business Loan | B15: =D13 -> 0 | C15: =C13% -> 0 | D15: =(D13*C13/12/100) -> 0 | E15: =(D13*C13/100) -> 0 | F15: =(D13*C13/SUM(D5:D14*C5:C14)*100)% -> 0
A16: Other Debt | B16: =D14 -> 0 | C16: =C14% -> 0 | D16: =(D14*C14/12/100) -> 0 | E16: =(D14*C14/100) -> 0 | F16: =(D14*C14/SUM(D5:D14*C5:C14)*100)% -> 0
A18: TOTAL INTEREST BURDEN
A19: Total Monthly Interest | B19: ₹ | C19: =SUM(D7:D16) -> 0 | D19: Interest cost each month
A20: Total Annual Interest | B20: ₹ | C20: =SUM(E7:E16) -> 0 | D20: Interest cost per year
A21: Total Interest Over Lifetime | B21: ₹ | C21: =SUM(E7:E16)*3 -> 0 | D21: If maintained 3 years
A23: INTEREST REDUCTION STRATEGIES
A24: Strategy | B24: Action | C24: Potential Savings (₹) | D24: Difficulty | E24: Impact
A25: Pay more than minimum | B25: Add extra ₹2,000-5,000/month to highest interest debt | C25: =('Interest Tracker'!B21*0.40) -> 0 | D25: Medium | E25: High
A26: Negotiate lower rates | B26: Call lender, ask for rate reduction (credit card: 8-15% reduction) | C26: =('Interest Tracker'!B21*0.25) -> 0 | D26: Medium | E26: Medium
A27: Balance transfer (credit card) | B27: Move 0% intro APR card (12-18 months interest-free) | C27: =('Interest Tracker'!B21*0.50) -> 0 | D27: High | E27: Very High
A28: Consolidation loan | B28: Roll multiple debts into single lower-rate loan | C28: =('Interest Tracker'!B21*0.30) -> 0 | D28: High | E28: High
A29: Debt settlement | B29: Negotiate to pay lump sum (impacts credit score) | C29: =('Interest Tracker'!B21*0.40) -> 0 | D29: Very High | E29: High
A31: PAYOFF SPEED SCENARIOS
A32: Scenario | B32: Monthly Payment | C32: Debt-Free In | D32: Total Interest Paid | E32: Monthly vs Minimum
A33: Minimum Payments Only | B33: =SUM('Debt Inventory'!E5:E14) -> 0 | C33: 60+ months | D33: =SUM(E7:E16)*5 -> 0 | E33: Current pace
A34: Minimum + ₹5,000 extra | B34: =SUM('Debt Inventory'!E5:E14)+5000 -> 0 | C34: 36-42 months | D34: =SUM(E7:E16)*3 -> 0 | E34: 18-24 months faster
A35: Minimum + ₹10,000 extra | B35: =SUM('Debt Inventory'!E5:E14)+10000 -> 0 | C35: 24-30 months | D35: =SUM(E7:E16)*2 -> 0 | E35: 30-36 months faster
A36: Minimum + ₹15,000 extra | B36: =SUM('Debt Inventory'!E5:E14)+15000 -> 0 | C36: 18-24 months | D36: =SUM(E7:E16)*1.5 -> 0 | E36: 36+ months faster
A38: INTEREST COMPARISON: OLD vs NEW SCENARIO
A39: Scenario | B39: Total Debt | C39: Avg Interest Rate | D39: Monthly Payment | E39: Total Interest (Lifetime) | F39: Debt-Free Date
A40: Current Situation | B40: =SUM('Debt Inventory'!D5:D14) -> 0 | C40: =AVERAGE('Debt Inventory'!C5:C14)% -> 0 | D40: =SUM('Debt Inventory'!E5:E14) -> 0 | E40: =SUM(E7:E16)*3 -> 0 | F40: TBD
A41: With ₹5k Extra/Month | B41: =SUM('Debt Inventory'!D5:D14) -> 0 | C41: =AVERAGE('Debt Inventory'!C5:C14)% -> 0 | D41: =SUM('Debt Inventory'!E5:E14)+5000 -> 0 | E41: =(SUM(E7:E16)*3)*0.70 -> 0 | F41: 6 months sooner
A42: After Negotiated Rates -2% | B42: =SUM('Debt Inventory'!D5:D14) -> 0 | C42: =(AVERAGE('Debt Inventory'!C5:C14)-2)% -> 0 | D42: =SUM('Debt Inventory'!E5:E14) -> 0 | E42: =(SUM(E7:E16)*3)*0.60 -> 0 | F42: 12 months sooner
A43: Ideal Scenario (All optimized) | B43: =SUM('Debt Inventory'!D5:D14) -> 0 | C43: =(AVERAGE('Debt Inventory'!C5:C14)-3)% -> 0 | D43: =SUM('Debt Inventory'!E5:E14)+10000 -> 0 | E43: =(SUM(E7:E16)*3)*0.40 -> 0 | F43: 24 months sooner

Sheet Milestones
A1: DEBT FREEDOM MILESTONES & PROGRESS TRACKER
A3: Track your journey to financial freedom with these celebration points.
A5: MAJOR MILESTONES
A6: Milestone | B6: Target Date | C6: Debt Remaining (₹) | D6: Amount Cleared | E6: Progress % | F6: Status
A8: 1st Debt Eliminated | B8: Target | C8: =SUM('Debt Inventory'!D5:D14)-'Debt Inventory'!D5 -> 0 | D8: =MIN('Debt Inventory'!D5:D14) -> 0 | E8: =(MIN('Debt Inventory'!D5:D14)/SUM('Debt Inventory'!D5:D14))*100% -> 0 | F8: Track smallest
A9: 25% CLEARED 🎯 | B9: Month 3-4 | C9: =SUM('Debt Inventory'!D5:D14)*0.75 -> 0 | D9: =SUM('Debt Inventory'!D5:D14)*0.25 -> 0 | E9: 25% | F9: Celebrate!
A10: 50% CLEARED (Halfway!) 🎉 | B10: Month 6-9 | C10: =SUM('Debt Inventory'!D5:D14)*0.50 -> 0 | D10: =SUM('Debt Inventory'!D5:D14)*0.50 -> 0 | E10: 50% | F10: Major milestone!
A11: 75% CLEARED 💪 | B11: Month 12-15 | C11: =SUM('Debt Inventory'!D5:D14)*0.25 -> 0 | D11: =SUM('Debt Inventory'!D5:D14)*0.75 -> 0 | E11: 75% | F11: Almost free!
A12: ALL DEBTS CLEARED! 🏆 | B12: Month 18-24 | C12: ₹0 | D12: =SUM('Debt Inventory'!D5:D14) -> 0 | E12: 100% | F12: DEBT FREE!
A14: MONTHLY PROGRESS CHECKLIST
A15: Month | B15: Target Action | C15: Debt Remaining (₹) | D15: Interest Saved | E15: Motivation Level | F15: Notes
A16: Month 1 | B16: Set up auto-payments, pick strategy | C16: =SUM('Debt Inventory'!D5:D14) -> 0 | D16: Track start | E16: 🔥 High | F16: Establish routine
A17: Month 2 | B17: Continue payments, no new debt | C17: =SUM('Debt Inventory'!D5:D14)*0.98 -> 0 | D17: =SUM(E7:E16)/12 -> 0 | E17: 🔥 High | F17: Stay committed
A18: Month 3 | B18: Review progress, celebrate first savings | C18: =SUM('Debt Inventory'!D5:D14)*0.95 -> 0 | D18: =(SUM(E7:E16)/12)*3 -> 0 | E18: 😊 Good | F18: First debt closing?
A19: Month 4 | B19: Negotiate lower rates if possible | C19: =SUM('Debt Inventory'!D5:D14)*0.92 -> 0 | D19: =(SUM(E7:E16)/12)*4 -> 0 | E19: 😊 Good | F19: Check credit report
A20: Month 5 | B20: Add any bonus/tax refund to debt | C20: =SUM('Debt Inventory'!D5:D14)*0.88 -> 0 | D20: =(SUM(E7:E16)/12)*5 -> 0 | E20: 😊 Good | F20: Extra payment boost
A21: Month 6 | B21: Celebrate 25% progress! | C21: =SUM('Debt Inventory'!D5:D14)*0.75 -> 0 | D21: =(SUM(E7:E16)/12)*6 -> 0 | E21: 😊 Good | F21: Quarter down!
A22: Month 9 | B22: Hitting momentum - continue! | C22: =SUM('Debt Inventory'!D5:D14)*0.62 -> 0 | D22: =(SUM(E7:E16)/12)*9 -> 0 | E22: 😊 Good | F22: 3 months in!
A23: Month 12 | B23: Review annual progress, adjust if needed | C23: =SUM('Debt Inventory'!D5:D14)*0.50 -> 0 | D23: =(SUM(E7:E16)/12)*12 -> 0 | E23: 🔥 High | F23: Halfway milestone!
A24: Month 18 | B24: Celebrate 75% progress! | C24: =SUM('Debt Inventory'!D5:D14)*0.25 -> 0 | D24: =(SUM(E7:E16)/12)*18 -> 0 | E24: 🔥 High | F24: Final stretch!
A25: Month 24 | B25: DEBT FREEDOM! 🎉 | C25: ₹0 | D25: =(SUM(E7:E16)/12)*24 -> 0 | E25: 🏆 Victorious | F25: You did it!
A27: CELEBRATING YOUR WINS
A28: When You Hit This Milestone | B28: Celebrate By | C28: Reward Budget | D28: Notes
A29: 1st Debt Paid Off | B29: Small celebration (₹500-1000) | C29: Budget: ₹500-1000 | D29: Cinema, dinner, or treat
A30: 25% Progress | B30: Weekend getaway or shopping spree | C30: Budget: ₹2,000-3,000 | D30: Mini vacation or hobby items
A31: 50% Progress (Halfway!) | B31: Bigger celebration! | C31: Budget: ₹5,000-10,000 | D31: Trip, gadget, or experience
A32: 75% Progress | B32: Splurge on yourself | C32: Budget: ₹5,000-10,000 | D32: Something you've wanted
A33: 100% DEBT FREE! | B33: Major celebration! 🎊 | C33: Budget: ₹15,000-25,000 | D33: Vacation, investment start, or big purchase
A35: POST-DEBT PLANNING
A36: After You're Debt Free | B36: Action | C36: Timeline | D36: Benefit
A37: Emergency Fund | B37: Build 6 months expenses | C37: 1-2 months | D37: Financial security
A38: Start Investing | B38: Begin SIP/ELSS for wealth building | C38: Immediately | D38: Long-term growth
A39: Build Credit | B39: Get credit card, use responsibly | C39: 3-6 months | D39: Better future rates
A40: Plan for Goals | B40: Vacation, home, education, retirement | C40: Ongoing | D40: Quality of life
