Workbook

Sheet Dashboard
A1: EMERGENCY FUND PLANNER - PERSONALIZED FINANCIAL SAFETY NET
A3: YOUR EMERGENCY FUND PROFILE
A4: Metric | B4: Current Value | C4: Target Value | D4: Progress % | E4: Status | F4: Action
A5: Total Emergency Fund | B5: ₹ | C5: =IF(SUM('Fund Analysis'!C7:C11)>0,SUM('Fund Analysis'!C7:C11),0) -> 0 | D5: =IF('Fund Analysis'!C12>0,'Fund Analysis'!C12,0) -> 0 | E5: =IF(B7>=C7,"✓ On Track","📈 Building") -> 0 | F5: Continue saving
A6: Target Fund (6 months) | B6: ₹ | C6: ='Expense Analysis'!B16 -> 0 | D6: =(B6/'Expense Analysis'!B16)*100% -> 0 | E6: =IF(B6>='Expense Analysis'!B16,"✓ ACHIEVED","In Progress") -> 0 | F6: Keep growing
A7: Months of Expenses Covered | B7: =IF('Expense Analysis'!B16>0,B6/'Expense Analysis'!B12,0) -> 0 | C7: 6 | D7: =(B8/C8)*100% -> 0 | E7: =IF(B8>=3,"✓ Safe","❌ Risky") -> 0 | F7: Accelerate savings
A8: Annual Savings Rate | B8: ₹ | C8: ='Expense Analysis'!B25 -> 0 | D8: =(B9/'Expense Analysis'!B25)*100% -> 0 | E8: =IF(B9>='Expense Analysis'!B25,"✓ On Budget","⚠️ Review") -> 0 | F8: Adjust SIP
A9: Fund Allocation Status | B9: Complete | C9: Optimized | E9: =IF('Fund Analysis'!C7=0,"❌ No allocation","✓ Allocated") -> 0 | F9: Review allocation
A11: YOUR EMERGENCY FUND TIMELINE
A12: Stage | B12: Current Amount (₹) | C12: Target Amount (₹) | D12: Months Away | E12: Progress | F12: Recommendation
A13: Stage 1 (1 month) | B13: =IF(B6<'Expense Analysis'!B12,'Expense Analysis'!B12,"✓ Achieved") -> 0 | C13: ='Expense Analysis'!B12 -> 0 | D13: =IF(B14<C14,CEILING((C14-B14)/'Expense Analysis'!B25/12),0) -> 0 | E13: =IF(B14>=C14,"✓ Complete",ROUND(B14/C14*100,0)&"%") -> 0 | F13: Quick access to 1 month buffer
A14: Stage 2 (3 months) | B14: =IF(B6<'Expense Analysis'!B14,'Expense Analysis'!B14,"✓ Achieved") -> 0 | C14: ='Expense Analysis'!B14 -> 0 | D14: =IF(B15<C15,CEILING((C15-B15)/'Expense Analysis'!B25/12),0) -> 0 | E14: =IF(B15>=C15,"✓ Complete",ROUND(B15/C15*100,0)&"%") -> 0 | F14: Basic emergency coverage
A15: Stage 3 (6 months) | B15: =IF(B6<'Expense Analysis'!B16,'Expense Analysis'!B16,"✓ Achieved") -> 0 | C15: ='Expense Analysis'!B16 -> 0 | D15: =IF(B16<C16,CEILING((C16-B16)/'Expense Analysis'!B25/12),0) -> 0 | E15: =IF(B16>=C16,"✓ Complete",ROUND(B16/C16*100,0)&"%") -> 0 | F15: Recommended goal
A16: Stage 4 (9 months) | B16: =IF(B6<'Expense Analysis'!B12*9,'Expense Analysis'!B12*9,"✓ Achieved") -> 0 | C16: ='Expense Analysis'!B12*9 -> 0 | D16: =IF(B17<C17,CEILING((C17-B17)/'Expense Analysis'!B25/12),0) -> 0 | E16: =IF(B17>=C17,"✓ Complete",ROUND(B17/C17*100,0)&"%") -> 0 | F16: Extended job loss protection
A17: Stage 5 (12 months) | B17: =IF(B6<'Expense Analysis'!B12*12,'Expense Analysis'!B12*12,"✓ Achieved") -> 0 | C17: ='Expense Analysis'!B12*12 -> 0 | D17: =IF(B18<C18,CEILING((C18-B18)/'Expense Analysis'!B25/12),0) -> 0 | E17: =IF(B18>=C18,"✓ Complete",ROUND(B18/C18*100,0)&"%") -> 0 | F17: Maximum financial security
A19: QUICK INSIGHTS
A20: Insight | B20: Value | C20: Impact | D20: Timeline | E20: Action
A21: Monthly Essential Expenses | B21: ₹ | C21: ='Expense Analysis'!B12 -> 0 | D21: Your baseline safety amount | E21: Monthly | F21: Track & review quarterly
A22: Recommended Target (6 Mo) | B22: ₹ | C22: ='Expense Analysis'!B16 -> 0 | D22: Ideal emergency cushion | E22: Ongoing | F22: Priority goal
A23: Current Coverage Status | B23: =B8&" months" -> 0 | C23: Out of 6 months needed | D23: Financial security level | E23: Ongoing | F23: =IF(B8>=6,"✓ Secure","⚠️ Build more") -> 0
A24: Savings Required (Monthly) | B24: ₹ | C24: =IF('Expense Analysis'!B25<'Savings Timeline'!C16,'Savings Timeline'!C16,'Expense Analysis'!B25) -> 0 | D24: To reach 6-month goal | E24: Monthly SIP | F24: Set up auto-transfer
A25: Months to Reach Goal | B25: =IF('Savings Timeline'!C16>0,CEILING('Expense Analysis'!B16/'Savings Timeline'!C16),0) -> 0 | C25: months from now | D25: At current savings rate | E25: Deadline | F25: =IF(B24<12,"✓ Achievable","Needs acceleration") -> 0
A26: Best Liquid Asset Mix | B26: See Fund Allocation | C26: Optimize returns + liquidity | D26: Recommended allocation | E26: Review | F26: =IF('Fund Analysis'!C12>0,"✓ Configured","Set up now") -> 0
A28: FUND ALLOCATION OVERVIEW
A29: Asset Type | B29: Amount Allocated (₹) | C29: % of Total Fund | D29: Return Rate | E29: Liquidity | F29: Purpose
A30: Savings Account | B30: ='Fund Analysis'!C7 -> 0 | C30: =IF(SUM('Fund Analysis'!$C$7:$C$11)>0,B32/SUM('Fund Analysis'!$C$7:$C$11)*100,0)% -> 0 | D30: 3-4% | E30: Instant (24hrs) | F30: Immediate emergencies
A31: Liquid Funds | B31: ='Fund Analysis'!C8 -> 0 | C31: =IF(SUM('Fund Analysis'!$C$7:$C$11)>0,B33/SUM('Fund Analysis'!$C$7:$C$11)*100,0)% -> 0 | D31: 4-5% | E31: T+1 (1-2 days) | F31: Primary emergency buffer
A32: Short-term FD (3-6 months) | B32: ='Fund Analysis'!C9 -> 0 | C32: =IF(SUM('Fund Analysis'!$C$7:$C$11)>0,B34/SUM('Fund Analysis'!$C$7:$C$11)*100,0)% -> 0 | D32: 6-7% | E32: 5-7 days | F32: Medium-term reserves
A33: Fixed Deposit (6-12 months) | B33: ='Fund Analysis'!C10 -> 0 | C33: =IF(SUM('Fund Analysis'!$C$7:$C$11)>0,B35/SUM('Fund Analysis'!$C$7:$C$11)*100,0)% -> 0 | D33: 7-8% | E33: Pre-closure penalty | F33: Longer-term stability
A34: Money Market Fund | B34: ='Fund Analysis'!C11 -> 0 | C34: =IF(SUM('Fund Analysis'!$C$7:$C$11)>0,B36/SUM('Fund Analysis'!$C$7:$C$11)*100,0)% -> 0 | D34: 5-6% | E34: T+1 (1-2 days) | F34: Flexible high yield
A35: TOTAL EMERGENCY FUND | B35: =SUM(B32:B36) -> 0 | C35: 100% | D35: Blended avg | E35: Optimized | F35: Complete safety net
A37: EMERGENCY FUND HEALTH CHECK
A38: Criteria | B38: Status | C38: Rating | D38: Recommendation | E38: Risk Level | F38: Priority
A39: Adequacy (Months Covered) | B39: =TEXT(B8,"0.0")&" months","=IF(B8>=6,"✓ Excellent",IF(B8>=3,"Good","Needs work")) -> 0 | C39: =IF(B8>=6,"⭐⭐⭐",IF(B8>=3,"⭐⭐","⭐")) -> 0 | D39: =IF(B8<3,"Urgent: Build to 3 months",IF(B8<6,"Grow to 6 months","Expand to 9-12 months")) -> 0 | E39: =IF(B8<3,"HIGH",IF(B8<6,"MEDIUM","LOW")) -> 0 | F39: =IF(B8<3,"URGENT",IF(B8<6,"Important","Optional")) -> 0
A40: Liquidity Access | B40: All assets T+1 or faster | C40: ✓ Excellent | D40: ⭐⭐⭐ | E40: Maintain liquid allocation | F40: LOW | G40: Monitor
A41: Return Rate | B41: =ROUND(AVERAGE('Fund Analysis'!D7:D11),2)&"%" -> 0 | C41: =IF(AVERAGE('Fund Analysis'!D7:D11)>=5,"Good","Fair") -> 0 | D41: =IF(AVERAGE('Fund Analysis'!D7:D11)>=5,"⭐⭐⭐","⭐⭐") -> 0 | E41: Consider adding liquid funds | F41: LOW | G41: Optimize
A42: Savings Consistency | B42: =IF('Savings Timeline'!C16>0,"On track","Below target") -> 0 | C42: =IF('Savings Timeline'!C16>'Expense Analysis'!B25*0.8,"✓ Good","⚠️ Review") -> 0 | D42: =IF('Savings Timeline'!C16>'Expense Analysis'!B25*0.8,"⭐⭐","⭐") -> 0 | E42: Increase SIP if possible | F42: MEDIUM | G42: Important
A43: Goal Achievement Timeline | B43: =B24&" months to 6-month goal" -> 0 | C43: =IF(B24<=12,"✓ Achievable","Needs boost") -> 0 | D43: =IF(B24<=12,"⭐⭐⭐","⭐") -> 0 | E43: =IF(B24>12,"Increase monthly savings","Stay consistent") -> 0 | F43: =IF(B24>12,"HIGH","MEDIUM") -> 0 | G43: Important
A45: EMERGENCY SCENARIO ANALYSIS
A46: Scenario | B46: Monthly Cost | C46: Duration | D46: Total Need | E46: Current Coverage | F46: Shortfall | G46: Status
...

Sheet Expense Analysis
A1: EXPENSE ANALYSIS - CALCULATE YOUR ESSENTIAL MONTHLY COSTS
A3: List all your monthly essential expenses below. These form the basis of your emergency fund calculation.
A5: MONTHLY ESSENTIAL EXPENSES
A6: Expense Category | B6: Monthly Cost (₹) | C6: Annual Cost (₹) | D6: % of Total | E6: Frequency | F6: Notes
A7: Rent/Home Loan EMI | B7: ₹45000 | C7: =B7*12 -> 0 | D7: =B7/B17*100% -> 0 | E7: Monthly | F7: Fixed housing cost
A8: Groceries & Food | B8: ₹15000 | C8: =B8*12 -> 0 | D8: =B8/B17*100% -> 0 | E8: Monthly | F8: Essential food items only
A9: Utilities (Electricity, Water, Gas) | B9: ₹4000 | C9: =B9*12 -> 0 | D9: =B9/B17*100% -> 0 | E9: Monthly | F9: Basic utility bills
A10: Internet & Mobile | B10: ₹2500 | C10: =B10*12 -> 0 | D10: =B10/B17*100% -> 0 | E10: Monthly | F10: Essential connectivity
A11: School/Education Fees | B11: ₹8000 | C11: =B11*12 -> 0 | D11: =B11/B17*100% -> 0 | E11: Monthly | F11: Children's education
A12: Health & Medical | B12: ₹3500 | C12: =B12*12 -> 0 | D12: =B12/B17*100% -> 0 | E12: Monthly | F12: Regular medical costs
A13: Insurance Premiums | B13: ₹5500 | C13: =B13*12 -> 0 | D13: =B13/B17*100% -> 0 | E13: Monthly | F13: Health, life, motor, home
A14: Vehicle Fuel/Maintenance | B14: ₹4000 | C14: =B14*12 -> 0 | D14: =B14/B17*100% -> 0 | E14: Monthly | F14: Necessary transport
A15: Household Help/Services | B15: ₹2000 | C15: =B15*12 -> 0 | D15: =B15/B17*100% -> 0 | E15: Monthly | F15: Maid, laundry essentials
A16: Other Essentials | B16: ₹1000 | C16: =B16*12 -> 0 | D16: =B16/B17*100% -> 0 | E16: Monthly | F16: Miscellaneous needs
A18: MONTHLY & ANNUAL TOTALS
A19: Total Monthly Essential Expenses | B19: =SUM(B7:B16) -> 0 | C19: =SUM(C7:C16) -> 0 | D19: 100% | E19: Essential only | F19: Your baseline safety amount
A20: Buffer (10% cushion) | B20: =B17*0.10 -> 0 | C20: =C17*0.10 -> 0 | E20: Unexpected items | F20: Small surprises
A21: TOTAL WITH BUFFER | B21: =B17+B18 -> 0 | C21: =C17+C18 -> 0 | D21: 110% | F21: Realistic monthly need
A23: EMERGENCY FUND TARGETS
A24: Duration | B24: Formula | C24: Amount (₹) | D24: When Needed | E24: Coverage Status | F24: Priority
A25: 1 Month Emergency | B25: =B17*1 -> 0 | C25: =B20 -> 0 | D25: Immediate crisis | E25: =IF(B20>0,"Calculate","0") -> 0 | F25: HIGH
A26: 3 Months Emergency (Basic) | B26: =B17*3 -> 0 | C26: =B17*3 -> 0 | D26: Job loss, illness | E26: =IF(B21>0,"Calculate","0") -> 0 | F26: HIGH
A27: 6 Months Emergency (Recommended) | B27: =B17*6 -> 0 | C27: =B17*6 -> 0 | D27: Extended hardship | E27: =IF(B22>0,"Calculate","0") -> 0 | F27: MEDIUM
A28: 9 Months Emergency (Safe) | B28: =B17*9 -> 0 | C28: =B17*9 -> 0 | D28: Prolonged crisis | E28: =IF(B23>0,"Calculate","0") -> 0 | F28: MEDIUM
A29: 12 Months Emergency (Secure) | B29: =B17*12 -> 0 | C29: =B17*12 -> 0 | D29: Maximum safety | E29: =IF(B24>0,"Calculate","0") -> 0 | F29: LOW
A31: YOUR INCOME & SAVINGS CAPACITY
A32: Metric | B32: Monthly Amount (₹) | C32: Annual Amount (₹) | D32: % of Income | E32: Status | F32: Notes
A33: Gross Monthly Income | B33: ₹125000 | C33: =B26*12 -> 0 | D33: 100% | E33: Your baseline | F33: Before taxes & deductions
A34: Net Take-home Income | B34: ₹90000 | C34: =B27*12 -> 0 | D34: 72% | E34: After taxes | F34: Actual spending power
A35: Total Monthly Expenses | B35: =B19 -> 0 | C35: =C19 -> 0 | D35: =B28/B26*100% -> 0 | E35: Essential + buffer | F35: All essential costs
A36: Monthly Surplus (Before Savings) | B36: =B27-B28 -> 0 | C36: =C27-C28 -> 0 | D36: =(B29/B27)*100% -> 0 | E36: Available to save | F36: After all expenses
A37: Target Monthly Savings (SIP) | B37: =IF(B29>0,MIN(B29,B17/6),0) -> 0 | C37: =C30*12 -> 0 | D37: =IF(B30>0,(B30/B27)*100%,0)% -> 0 | E37: Recommended saving | F37: To reach 6-month goal
A38: Savings Rate (% of income) | B38: =(B30/B27)*100% -> 0 | C38: =(C30/C27)*100% -> 0 | E38: Your capacity | F38: Percentage saved annually

Sheet Fund Analysis
A1: FUND ALLOCATION & LIQUID ASSET STRATEGY
A3: Optimize your emergency fund across safe, liquid assets that balance accessibility and returns.
A5: EMERGENCY FUND ALLOCATION
A6: Asset Type | B6: Allocation (₹) | C6: % of Total | D6: Annual Return Rate | E6: Liquidity Timeline | F6: Risk Level
A7: Savings Account (Primary) | B7: =IF('Expense Analysis'!B17*1>0,'Expense Analysis'!B17*1,0) -> 0 | C7: =IF(SUM(C7:C11)>0,C7/SUM($C$7:$C$11)*100%,0) -> 0 | D7: 3-4% | E7: Instant (24 hours) | F7: Very Low
A8: Liquid Funds (Core) | B8: =IF('Expense Analysis'!B17*3>0,'Expense Analysis'!B17*3,0) -> 0 | C8: =IF(SUM(C7:C11)>0,C8/SUM($C$7:$C$11)*100%,0) -> 0 | D8: 4-5% | E8: T+1 (1-2 days) | F8: Very Low
A9: Short-term FD (3-6 months) | B9: =IF('Expense Analysis'!B17*1.5>0,'Expense Analysis'!B17*1.5,0) -> 0 | C9: =IF(SUM(C7:C11)>0,C9/SUM($C$7:$C$11)*100%,0) -> 0 | D9: 6-7% | E9: 5-7 days | F9: Low
A10: Fixed Deposit (6-12 months) | B10: =IF('Expense Analysis'!B17*0.5>0,'Expense Analysis'!B17*0.5,0) -> 0 | C10: =IF(SUM(C7:C11)>0,C10/SUM($C$7:$C$11)*100%,0) -> 0 | D10: 7-8% | E10: Pre-closure penalty | F10: Low
A11: Money Market Fund | B11: =IF('Expense Analysis'!B17*0.5>0,'Expense Analysis'!B17*0.5,0) -> 0 | C11: =IF(SUM(C7:C11)>0,C11/SUM($C$7:$C$11)*100%,0) -> 0 | D11: 5-6% | E11: T+1 (1-2 days) | F11: Very Low
A12: TOTAL EMERGENCY FUND | B12: =SUM(C7:C11) -> 0 | C12: 100% | D12: =AVERAGE(D7:D11) -> 0 | E12: Mixed | F12: Very Low
A14: DETAILED ASSET BREAKDOWN
A15: Asset Category | B15: Current Balance (₹) | C15: Target Balance (₹) | D15: Gap (₹) | E15: Action | F15: Timeline
A16: Savings Account | B16: =IF(C7>0,C7,0) -> 0 | C16: =IF('Expense Analysis'!B17*1>0,'Expense Analysis'!B17*1,0) -> 0 | D16: =MAX(0,D16-C16) -> 0 | E16: =IF(E16>0,"Build up","Adequate") -> 0 | F16: Immediate
A17: Liquid Funds | B17: =IF(C8>0,C8,0) -> 0 | C17: =IF('Expense Analysis'!B17*3>0,'Expense Analysis'!B17*3,0) -> 0 | D17: =MAX(0,D17-C17) -> 0 | E17: =IF(E17>0,"Invest now","Adequate") -> 0 | F17: This month
A18: Short-term FD | B18: =IF(C9>0,C9,0) -> 0 | C18: =IF('Expense Analysis'!B17*1.5>0,'Expense Analysis'!B17*1.5,0) -> 0 | D18: =MAX(0,D18-C18) -> 0 | E18: =IF(E18>0,"Lock funds","Adequate") -> 0 | F18: Next quarter
A19: Long-term FD | B19: =IF(C10>0,C10,0) -> 0 | C19: =IF('Expense Analysis'!B17*0.5>0,'Expense Analysis'!B17*0.5,0) -> 0 | D19: =MAX(0,D19-C19) -> 0 | E19: =IF(E19>0,"Open new FD","Adequate") -> 0 | F19: Next quarter
A20: Money Market Fund | B20: =IF(C11>0,C11,0) -> 0 | C20: =IF('Expense Analysis'!B17*0.5>0,'Expense Analysis'!B17*0.5,0) -> 0 | D20: =MAX(0,D20-C20) -> 0 | E20: =IF(E20>0,"Explore options","Adequate") -> 0 | F20: Review
A22: ASSET ALLOCATION RULES (By Life Stage)
A23: Life Stage | B23: Savings Account | C23: Liquid Funds | D23: ST FD (3-6mo) | E23: LT FD (6-12mo) | F23: Money Market | G23: Best For
A24: Single/Young (Entry-level job) | B24: 40% | C24: 40% | D24: 10% | E24: 0% | F24: 10% | G24: Maximum flexibility
A25: Married (Stable income) | B25: 30% | C25: 45% | D25: 15% | E25: 5% | F25: 5% | G25: Balanced approach
A26: With dependents (2+ kids) | B26: 20% | C26: 40% | D26: 20% | E26: 10% | F26: 10% | G26: Growth + safety
A27: Entrepreneur (Unstable income) | B27: 50% | C27: 30% | D27: 10% | E27: 5% | F27: 5% | G27: Maximum liquidity
A28: Retired (No income) | B28: 30% | C28: 35% | D28: 15% | E28: 15% | F28: 5% | G28: Higher allocation needed
A30: ANNUAL EXPECTED RETURNS
A31: Asset Type | B31: Amount (₹) | C31: Return Rate | D31: Annual Income (₹) | E31: % Contribution | F31: Notes
A32: Savings Account | B32: =C7 -> 0 | C32: =D7 -> 0 | D32: =C7*D7/100 -> 0 | E32: =D30/SUM($D$30:$D$34) -> 0 | F32: Lowest yield
A33: Liquid Funds | B33: =C8 -> 0 | C33: =D8 -> 0 | D33: =C8*D8/100 -> 0 | E33: =D31/SUM($D$30:$D$34) -> 0 | F33: Best liquidity + return
A34: Short-term FD | B34: =C9 -> 0 | C34: =D9 -> 0 | D34: =C9*D9/100 -> 0 | E34: =D32/SUM($D$30:$D$34) -> 0 | F34: Good returns
A35: Long-term FD | B35: =C10 -> 0 | C35: =D10 -> 0 | D35: =C10*D10/100 -> 0 | E35: =D33/SUM($D$30:$D$34) -> 0 | F35: Highest returns
A36: Money Market Fund | B36: =C11 -> 0 | C36: =D11 -> 0 | D36: =C11*D11/100 -> 0 | E36: =D34/SUM($D$30:$D$34) -> 0 | F36: Balance returns
A37: TOTAL EXPECTED ANNUAL RETURN | B37: =SUM(C30:C34) -> 0 | C37: Blended avg | D37: =SUM(D30:D34) -> 0 | E37: 100% | F37: Fund will grow

Sheet Savings Timeline
A1: SAVINGS TIMELINE & PROGRESS TRACKER
A3: Track your progress toward building your emergency fund with monthly milestones and goals.
A5: SAVINGS PLAN DETAILS
A6: Metric | B6: Your Situation | C6: Calculation | D6: Result | E6: Status | F6: Notes
A7: Target Fund Amount | B7: 6 months expenses | C7: ='Expense Analysis'!B17*6 -> 0 | D7: ='Expense Analysis'!B22 -> 0 | E7: Goal amount | F7: Recommended target
A8: Current Fund Status | B8: Need to track | C8: Total of all assets | D8: =SUM('Fund Analysis'!C7:C11) -> 0 | E8: Current balance | F8: Update monthly
A9: Funds Remaining to Reach Goal | B9: Gap to target | C9: =C7-C8 -> 0 | D9: =MAX(0,'Expense Analysis'!B22-SUM('Fund Analysis'!C7:C11)) -> 0 | E9: Amount needed | F9: Priority gap
A10: Monthly Savings Rate | B10: Your capacity | C10: From expense analysis | D10: ='Expense Analysis'!B30 -> 0 | E10: Your SIP | F10: Increase if possible
A11: Months to Reach Goal | B11: Timeline | C11: =C9/C10 -> 0 | D11: =IF(C10>0,CEILING(C9/C10),999) -> 0 | E11: Deadline | F11: Adjust savings rate
A13: MONTHLY SAVINGS PROGRESS
A14: Month | B14: Target Amount | C14: Your Contribution | D14: Current Balance | E14: Progress to Goal % | F14: Status
A15: January 2026 | B15: ='Expense Analysis'!B17 -> 0 | C15: ='Expense Analysis'!B30 -> 0 | D15: ='Expense Analysis'!B30 -> 0 | E15: =IF('Expense Analysis'!B30>0,('Expense Analysis'!B30/'Expense Analysis'!B22)*100,0)% -> 0 | F15: Starting
A16: February 2026 | B16: ='Expense Analysis'!B17*2 -> 0 | C16: ='Expense Analysis'!B30 -> 0 | D16: =B18*C18 -> 0 | E16: =IF(B18>0,(B18/'Expense Analysis'!B22)*100,0)% -> 0 | F16: Growing
A17: March 2026 | B17: ='Expense Analysis'!B17*3 -> 0 | C17: ='Expense Analysis'!B30 -> 0 | D17: =B19*C19 -> 0 | E17: =IF(B19>0,(B19/'Expense Analysis'!B22)*100,0)% -> 0 | F17: On track
A18: April 2026 | B18: ='Expense Analysis'!B17*4 -> 0 | C18: ='Expense Analysis'!B30 -> 0 | D18: =B20*C20 -> 0 | E18: =IF(B20>0,(B20/'Expense Analysis'!B22)*100,0)% -> 0 | F18: Building
A19: May 2026 | B19: ='Expense Analysis'!B17*5 -> 0 | C19: ='Expense Analysis'!B30 -> 0 | D19: =B21*C21 -> 0 | E19: =IF(B21>0,(B21/'Expense Analysis'!B22)*100,0)% -> 0 | F19: Progressing
A20: June 2026 | B20: ='Expense Analysis'!B17*6 -> 0 | C20: ='Expense Analysis'!B30 -> 0 | D20: =B22*C22 -> 0 | E20: =IF(B22>0,(B22/'Expense Analysis'!B22)*100,0)% -> 0 | F20: Accelerating
A21: July 2026 | B21: ='Expense Analysis'!B17*7 -> 0 | C21: ='Expense Analysis'!B30 -> 0 | D21: =B23*C23 -> 0 | E21: =IF(B23>0,(B23/'Expense Analysis'!B22)*100,0)% -> 0 | F21: Momentum
A22: August 2026 | B22: ='Expense Analysis'!B17*8 -> 0 | C22: ='Expense Analysis'!B30 -> 0 | D22: =B24*C24 -> 0 | E22: =IF(B24>0,(B24/'Expense Analysis'!B22)*100,0)% -> 0 | F22: Halfway
A23: September 2026 | B23: ='Expense Analysis'!B17*9 -> 0 | C23: ='Expense Analysis'!B30 -> 0 | D23: =B25*C25 -> 0 | E23: =IF(B25>0,(B25/'Expense Analysis'!B22)*100,0)% -> 0 | F23: Strong
A24: October 2026 | B24: ='Expense Analysis'!B17*10 -> 0 | C24: ='Expense Analysis'!B30 -> 0 | D24: =B26*C26 -> 0 | E24: =IF(B26>0,(B26/'Expense Analysis'!B22)*100,0)% -> 0 | F24: Excellent
A25: November 2026 | B25: ='Expense Analysis'!B17*11 -> 0 | C25: ='Expense Analysis'!B30 -> 0 | D25: =B27*C27 -> 0 | E25: =IF(B27>0,(B27/'Expense Analysis'!B22)*100,0)% -> 0 | F25: Almost there
A26: December 2026 | B26: ='Expense Analysis'!B17*12 -> 0 | C26: ='Expense Analysis'!B30 -> 0 | D26: =B28*C28 -> 0 | E26: =IF(B28>0,(B28/'Expense Analysis'!B22)*100,0)% -> 0 | F26: =IF(B28>='Expense Analysis'!B22,"✓ GOAL MET","Close") -> 0
A27: YEAR 1 TOTAL | B27: ='Expense Analysis'!B17*12 -> 0 | C27: =SUM(C18:C29) -> 0 | D27: =B29*C18 -> 0 | E27: =IF(B29>0,(B29/'Expense Analysis'!B22)*100,0)% -> 0 | F27: One year progress
A29: MILESTONE ACHIEVEMENTS
A30: Milestone | B30: Target Date | C30: Target Amount | D30: Current Status | E30: Days Away | F30: Action
A31: 1 Month Buffer | B31: =TODAY()+120 -> 0 | C31: ='Expense Analysis'!B17 -> 0 | D31: Not yet achieved | E31: =DAYS(C33,'Expense Analysis'!B17) -> 0 | F31: Priority
A32: 3 Month Basic | B32: =TODAY()+240 -> 0 | C32: ='Expense Analysis'!B14 -> 0 | D32: Not yet achieved | E32: =DAYS(C34,'Expense Analysis'!B14) -> 0 | F32: Build immediately
A33: 6 Month Recommended | B33: =TODAY()+365 -> 0 | C33: ='Expense Analysis'!B16 -> 0 | D33: Target goal | E33: =DAYS(C35,'Expense Analysis'!B16) -> 0 | F33: Main objective
A34: 9 Month Extended | B34: =TODAY()+545 -> 0 | C34: ='Expense Analysis'!B12*9 -> 0 | D34: Future goal | E34: =DAYS(C36,0) -> 0 | F34: Long-term
A35: 12 Month Secure | B35: =TODAY()+730 -> 0 | C35: ='Expense Analysis'!B12*12 -> 0 | D35: Maximum safety | E35: =DAYS(C37,0) -> 0 | F35: Ultimate goal
A37: AUTOMATED SAVINGS SETUP
A38: Setup Item | B38: Provider/Account | C38: Monthly Amount | D38: Start Date | E38: Type | F38: Status
A39: Auto-transfer to Savings | B39: Your Bank | C39: =CEILING('Expense Analysis'!B30*0.40) -> 0 | D39: 2026-01-05 | E39: NEFT/Auto debit | F39: Setup
A40: Liquid Fund SIP | B40: Mutual Fund App | C40: =CEILING('Expense Analysis'!B30*0.40) -> 0 | D40: 2026-01-05 | E40: SIP Auto debit | F40: Setup
A41: Short-term FD | B41: Bank/RBI platform | C41: =CEILING('Expense Analysis'!B30*0.15) -> 0 | D41: 2026-01-20 | E41: Lump sum monthly | F41: Plan
A42: Money Market Fund | B42: Brokerage/MF | C42: =CEILING('Expense Analysis'!B30*0.05) -> 0 | D42: 2026-02-01 | E42: SIP Auto debit | F42: Plan
A43: TOTAL MONTHLY AUTOMATION | B43: Multiple channels | C43: =SUM(C41:C44) -> 0 | D43: Starting now | E43: Fully automated | F43: Recommended

Sheet Growth Tracker
A1: EMERGENCY FUND GROWTH & MONITORING
A3: Monitor your emergency fund growth, track actual vs target progress, and review performance.
A5: ACTUAL VS TARGET PROGRESS
A6: Month | B6: Opening Balance | C6: Monthly Contribution | D6: Interest Earned | E6: Total Balance | F6: Target Balance | G6: Variance %
A7: Jan 2026 | B7: ₹0 | C7: ='Expense Analysis'!B30 -> 0 | D7: ₹0 | E7: ='Expense Analysis'!B30 -> 0 | F7: =SUM('Savings Timeline'!C18:C29)/12 -> 0 | G7: =IF(D8>E8,"Ahead","On track") -> 0
A8: Feb 2026 | B8: =D8 -> 0 | C8: ='Expense Analysis'!B30 -> 0 | D8: =D8*AVERAGE('Fund Analysis'!D7:D11)/12/100 -> 0 | E8: =D8+B9+C9 -> 0 | F8: =SUM('Savings Timeline'!C18:C29)/12*2 -> 0 | G8: =IF(D9>E9,"Ahead","On track") -> 0
A9: Mar 2026 | B9: =D9 -> 0 | C9: ='Expense Analysis'!B30 -> 0 | D9: =D9*AVERAGE('Fund Analysis'!D7:D11)/12/100 -> 0 | E9: =D9+B10+C10 -> 0 | F9: =SUM('Savings Timeline'!C18:C29)/12*3 -> 0 | G9: =IF(D10>E10,"Ahead","On track") -> 0
A10: Apr 2026 | B10: =D10 -> 0 | C10: ='Expense Analysis'!B30 -> 0 | D10: =D10*AVERAGE('Fund Analysis'!D7:D11)/12/100 -> 0 | E10: =D10+B11+C11 -> 0 | F10: =SUM('Savings Timeline'!C18:C29)/12*4 -> 0 | G10: =IF(D11>E11,"Ahead","On track") -> 0
A11: May 2026 | B11: =D11 -> 0 | C11: ='Expense Analysis'!B30 -> 0 | D11: =D11*AVERAGE('Fund Analysis'!D7:D11)/12/100 -> 0 | E11: =D11+B12+C12 -> 0 | F11: =SUM('Savings Timeline'!C18:C29)/12*5 -> 0 | G11: =IF(D12>E12,"Ahead","On track") -> 0
A12: Jun 2026 | B12: =D12 -> 0 | C12: ='Expense Analysis'!B30 -> 0 | D12: =D12*AVERAGE('Fund Analysis'!D7:D11)/12/100 -> 0 | E12: =D12+B13+C13 -> 0 | F12: =SUM('Savings Timeline'!C18:C29)/12*6 -> 0 | G12: =IF(D13>E13,"Ahead","On track") -> 0
A13: Jul 2026 | B13: =D13 -> 0 | C13: ='Expense Analysis'!B30 -> 0 | D13: =D13*AVERAGE('Fund Analysis'!D7:D11)/12/100 -> 0 | E13: =D13+B14+C14 -> 0 | F13: =SUM('Savings Timeline'!C18:C29)/12*7 -> 0 | G13: =IF(D14>E14,"Ahead","On track") -> 0
A14: Aug 2026 | B14: =D14 -> 0 | C14: ='Expense Analysis'!B30 -> 0 | D14: =D14*AVERAGE('Fund Analysis'!D7:D11)/12/100 -> 0 | E14: =D14+B15+C15 -> 0 | F14: =SUM('Savings Timeline'!C18:C29)/12*8 -> 0 | G14: =IF(D15>E15,"Ahead","On track") -> 0
A15: Sep 2026 | B15: =D15 -> 0 | C15: ='Expense Analysis'!B30 -> 0 | D15: =D15*AVERAGE('Fund Analysis'!D7:D11)/12/100 -> 0 | E15: =D15+B16+C16 -> 0 | F15: =SUM('Savings Timeline'!C18:C29)/12*9 -> 0 | G15: =IF(D16>E16,"Ahead","On track") -> 0
A16: Oct 2026 | B16: =D16 -> 0 | C16: ='Expense Analysis'!B30 -> 0 | D16: =D16*AVERAGE('Fund Analysis'!D7:D11)/12/100 -> 0 | E16: =D16+B17+C17 -> 0 | F16: =SUM('Savings Timeline'!C18:C29)/12*10 -> 0 | G16: =IF(D17>E17,"Ahead","On track") -> 0
A17: Nov 2026 | B17: =D17 -> 0 | C17: ='Expense Analysis'!B30 -> 0 | D17: =D17*AVERAGE('Fund Analysis'!D7:D11)/12/100 -> 0 | E17: =D17+B18+C18 -> 0 | F17: =SUM('Savings Timeline'!C18:C29)/12*11 -> 0 | G17: =IF(D18>E18,"Ahead","On track") -> 0
A18: Dec 2026 | B18: =D18 -> 0 | C18: ='Expense Analysis'!B30 -> 0 | D18: =D18*AVERAGE('Fund Analysis'!D7:D11)/12/100 -> 0 | E18: =D18+B19+C19 -> 0 | F18: =SUM('Savings Timeline'!C18:C29)/12*12 -> 0 | G18: =IF(D19>E19,"Ahead","On track") -> 0
A19: YEAR 1 TOTAL | B19: ₹0 | C19: =SUM(B8:B19) -> 0 | D19: =SUM(C8:C19) -> 0 | E19: =D19 -> 0 | F19: ='Expense Analysis'!B16 -> 0 | G19: =IF(D20>E20,"✓ Goal Met","In Progress") -> 0
A21: QUARTERLY PERFORMANCE REVIEW
A22: Quarter | B22: Opening Balance | C22: Contributions | D22: Interest Earned | E22: Ending Balance | F22: % Growth | G22: Status
A23: Q1 2026 | B23: ₹0 | C23: =SUM('Savings Timeline'!C18:C20) -> 0 | D23: =SUM('Growth Tracker'!C8:C10) -> 0 | E23: =D23+B23+C23 -> 0 | F23: =IF(D23>0,(D23/('Expense Analysis'!B30*3))*100,0)% -> 0 | G23: Starting
A24: Q2 2026 | B24: =D23 -> 0 | C24: =SUM('Savings Timeline'!C21:C23) -> 0 | D24: =SUM('Growth Tracker'!C11:C13) -> 0 | E24: =B24+B24+C24 -> 0 | F24: =IF(D24>0,(D24/D23-1)*100,0)% -> 0 | G24: Progressing
A25: Q3 2026 | B25: =D24 -> 0 | C25: =SUM('Savings Timeline'!C24:C26) -> 0 | D25: =SUM('Growth Tracker'!C14:C16) -> 0 | E25: =B25+B25+C25 -> 0 | F25: =IF(D25>0,(D25/D24-1)*100,0)% -> 0 | G25: Building
A26: Q4 2026 | B26: =D25 -> 0 | C26: =SUM('Savings Timeline'!C27:C29) -> 0 | D26: =SUM('Growth Tracker'!C17:C19) -> 0 | E26: =B26+B26+C26 -> 0 | F26: =IF(D26>0,(D26/D25-1)*100,0)% -> 0 | G26: =IF(D26>='Expense Analysis'!B16,"✓ Goal","Close") -> 0
A28: ANNUAL SUMMARY
A29: Metric | B29: Year 1 | C29: Year 2 Projection | D29: Year 3 Projection | E29: Status | F29: Notes
A30: Opening Balance | B30: ₹0 | C30: =D20 -> 0 | D30: =D20+('Expense Analysis'!B30*12) -> 0 | E30: Starting point | F30: Growth begins
A31: Annual Contribution | B31: =SUM('Savings Timeline'!C18:C29) -> 0 | C31: ='Expense Analysis'!B30*12 -> 0 | D31: ='Expense Analysis'!B30*12 -> 0 | E31: Consistent saving | F31: Regular SIP
A32: Annual Interest | B32: =SUM('Growth Tracker'!C8:C19) -> 0 | C32: =(D20+B31)*AVERAGE('Fund Analysis'!D7:D11)/100 -> 0 | D32: =(D20+B31+B32)*AVERAGE('Fund Analysis'!D7:D11)/100 -> 0 | E32: Growing returns | F32: Compound growth
A33: Closing Balance | B33: =D20 -> 0 | C33: =B30+B31+B32 -> 0 | D33: =B31+B32+B33 -> 0 | E33: Year-end balance | F33: Increasing each year
A34: % of Target Goal | B34: =(D20/'Expense Analysis'!B16)*100% -> 0 | C34: =(B31/'Expense Analysis'!B16)*100% -> 0 | D34: =(B32/'Expense Analysis'!B16)*100% -> 0 | E34: Progress % | F34: Track milestones
A35: Status | B35: =IF(D20>='Expense Analysis'!B16,"✓ Achieved","Building") -> 0 | C35: =IF(B31>='Expense Analysis'!B16,"✓ Achieved","✓ Achieved") -> 0 | D35: =IF(B32>='Expense Analysis'!B16*1.5,"✓ Enhanced","✓ Achieved") -> 0 | E35: Overall status | F35: Improving security
