Workbook

Sheet Dashboard
A1: INSURANCE NEEDS ANALYZER - COMPREHENSIVE AUDIT DASHBOARD
A3: YOUR INSURANCE SUMMARY
A4: Category | B4: Coverage Amount (₹) | C4: Annual Premium (₹) | D4: Renewal Date | E4: Status | F4: Action
A5: Health Insurance | B5: =SUM('Policy Tracker'!D7:D11) -> 0 | C5: =SUM('Policy Tracker'!E7:E11) -> 0 | D5: =INDEX('Policy Tracker'!F7:F11,MATCH(MAX('Policy Tracker'!G7:G11),'Policy Tracker'!G7:G11,0)) -> 0 | E5: =IF(INDEX('Policy Tracker'!G7:G11,MATCH(MAX('Policy Tracker'!G7:G11),'Policy Tracker'!G7:G11,0))<=90,"⚠️ Renew Soon","✓ Active") -> 0 | F5: Review coverage
A6: Term Life Insurance | B6: =SUM('Policy Tracker'!D12:D16) -> 0 | C6: =SUM('Policy Tracker'!E12:E16) -> 0 | D6: =INDEX('Policy Tracker'!F12:F16,MATCH(MAX('Policy Tracker'!G12:G16),'Policy Tracker'!G12:G16,0)) -> 0 | E6: =IF(INDEX('Policy Tracker'!G12:G16,MATCH(MAX('Policy Tracker'!G12:G16),'Policy Tracker'!G12:G16,0))<=90,"⚠️ Renew Soon","✓ Active") -> 0 | F6: Update sum assured
A7: Motor Insurance | B7: =SUM('Policy Tracker'!D17:D21) -> 0 | C7: =SUM('Policy Tracker'!E17:E21) -> 0 | D7: =INDEX('Policy Tracker'!F17:F21,MATCH(MAX('Policy Tracker'!G17:G21),'Policy Tracker'!G17:G21,0)) -> 0 | E7: =IF(INDEX('Policy Tracker'!G17:F21,MATCH(MAX('Policy Tracker'!G17:G21),'Policy Tracker'!G17:G21,0))<=90,"⚠️ Renew Soon","✓ Active") -> 0 | F7: Check NCB
A8: Home Insurance | B8: =SUM('Policy Tracker'!D22:D26) -> 0 | C8: =SUM('Policy Tracker'!E22:E26) -> 0 | D8: =INDEX('Policy Tracker'!F22:F26,MATCH(MAX('Policy Tracker'!G22:G26),'Policy Tracker'!G22:G26,0)) -> 0 | E8: =IF(INDEX('Policy Tracker'!G22:G26,MATCH(MAX('Policy Tracker'!G22:G26),'Policy Tracker'!G22:G26,0))<=90,"⚠️ Renew Soon","✓ Active") -> 0 | F8: Increase coverage
A9: Personal Accident | B9: =SUM('Policy Tracker'!D27:D31) -> 0 | C9: =SUM('Policy Tracker'!E27:E31) -> 0 | D9: =INDEX('Policy Tracker'!F27:F31,MATCH(MAX('Policy Tracker'!G27:G31),'Policy Tracker'!G27:G31,0)) -> 0 | E9: =IF(INDEX('Policy Tracker'!G27:G31,MATCH(MAX('Policy Tracker'!G27:G31),'Policy Tracker'!G27:G31,0))<=90,"⚠️ Renew Soon","✓ Active") -> 0 | F9: Review limits
A10: TOTAL ANNUAL PREMIUM | B10: ₹ | C10: =SUM(B8:B12) -> 0
A11: TOTAL COVERAGE | B11: ₹ | C11: =SUM(D8:D12) -> 0
A13: INSURANCE COVERAGE AUDIT
A14: Coverage Type | B14: Required Amount (₹) | C14: Current Coverage (₹) | D14: Coverage Gap (₹) | E14: Status | F14: Priority
A15: Health Insurance | B15: 500000 | C15: =IF('Policy Tracker'!D7>0,'Policy Tracker'!D7,0) -> 0 | D15: =MAX(0,B17-C17) -> 0 | E15: =IF(C17>=B17,"✓ Adequate","❌ Gap") -> 0 | F15: =IF(D17>100000,"HIGH",IF(D17>50000,"MEDIUM","LOW")) -> 0
A16: Term Life Insurance | B16: 7500000 | C16: =SUM('Policy Tracker'!D12:D16) -> 0 | D16: =MAX(0,B18-C18) -> 0 | E16: =IF(C18>=B18,"✓ Adequate","❌ Gap") -> 0 | F16: =IF(D18>500000,"HIGH",IF(D18>200000,"MEDIUM","LOW")) -> 0
A17: Motor Insurance | B17: 2000000 | C17: =SUM('Policy Tracker'!D17:D21) -> 0 | D17: =MAX(0,B19-C19) -> 0 | E17: =IF(C19>=B19,"✓ Adequate","❌ Gap") -> 0 | F17: =IF(D19>100000,"HIGH",IF(D19>50000,"MEDIUM","LOW")) -> 0
A18: Home Insurance | B18: 3000000 | C18: =SUM('Policy Tracker'!D22:D26) -> 0 | D18: =MAX(0,B20-C20) -> 0 | E18: =IF(C20>=B20,"✓ Adequate","❌ Gap") -> 0 | F18: =IF(D20>200000,"HIGH",IF(D20>100000,"MEDIUM","LOW")) -> 0
A19: Personal Accident | B19: 500000 | C19: =SUM('Policy Tracker'!D27:D31) -> 0 | D19: =MAX(0,B21-C21) -> 0 | E19: =IF(C21>=B21,"✓ Adequate","❌ Gap") -> 0 | F19: =IF(D21>100000,"HIGH",IF(D21>50000,"MEDIUM","LOW")) -> 0
A21: RENEWAL ALERTS
A22: Policy Name | B22: Renewal Date | C22: Days Until Renewal | D22: Current Premium | E22: Action Needed | F22: Status
A23: {=_xlfn._xlws.FILTER('Policy Tracker'!A7:A31,('Policy Tracker'!G7:G31<=90)*('Policy Tracker'!G7:G31>0))} -> 0 | B23: {=_xlfn._xlws.FILTER('Policy Tracker'!F7:F31,('Policy Tracker'!G7:G31<=90)*('Policy Tracker'!G7:G31>0))} -> 0 | C23: {=_xlfn._xlws.FILTER('Policy Tracker'!G7:G31,('Policy Tracker'!G7:G31<=90)*('Policy Tracker'!G7:G31>0))} -> 0 | D23: {=_xlfn._xlws.FILTER('Policy Tracker'!E7:E31,('Policy Tracker'!G7:G31<=90)*('Policy Tracker'!G7:G31>0))} -> 0 | E23: =IF('Policy Tracker'!G7:G31<=30,"❗ URGENT RENEW","⚠️ Renew Soon") -> 0 | F23: =IF('Policy Tracker'!G7:G31<=30,"Critical","Warning") -> 0
A25: QUICK STATS
A26: Metric | B26: Value | C26: Status | D26: Insight
A27: Total Policies Active | B27: =COUNTA('Policy Tracker'!A7:A31) -> 0 | C27: Active | D27: Number of active insurance policies
A28: Average Annual Premium | B28: ₹ | C28: =AVERAGE('Policy Tracker'!E7:E31) -> 0 | D28: Your average premium cost per policy
A29: Expiring Within 30 Days | B29: =COUNTIFS('Policy Tracker'!G7:G31,"<=30",'Policy Tracker'!G7:G31,">0") -> 0 | C29: Action Required | D29: Policies needing immediate renewal
A30: Expiring Within 90 Days | B30: =COUNTIFS('Policy Tracker'!G7:G31,"<=90",'Policy Tracker'!G7:G31,">0") -> 0 | C30: Planning Required | D30: Policies to renew soon
A31: Total Coverage Amount | B31: ₹ | C31: =SUM('Policy Tracker'!D7:D31) -> 0 | D31: Complete protection across all policies
A32: Total Premium (Yearly) | B32: ₹ | C32: =SUM('Policy Tracker'!E7:E31) -> 0 | D32: Annual insurance investment
A34: KEY RECOMMENDATIONS
A35: Priority | B35: Recommendation | C35: Expected Benefit | D35: Timeline | E35: Estimated Cost
A36: HIGH | B36: Increase health insurance to ₹10L | C36: Better medical coverage, fewer out-of-pocket expenses | D36: Immediate | E36: ₹8,000-12,000/year
A37: HIGH | B37: Buy term life insurance if missing | C37: Family financial security (10x annual income) | D37: Immediate | E37: ₹500-1,500/month
A38: MEDIUM | B38: Optimize motor insurance coverage | C38: Better claim settlement, NCB benefits | D38: Within 30 days | E38: Varied
A39: MEDIUM | B39: Review home insurance annually | C39: Keep pace with property value appreciation | D39: Yearly | E39: ₹2,000-5,000/year
A40: LOW | B40: Consider personal accident rider | C40: Additional ₹25L coverage | D40: Within 90 days | E40: ₹500-1,000/year

Sheet Policy Tracker
A1: INSURANCE POLICY TRACKER - MANAGE ALL YOUR POLICIES
A3: Add all your insurance policies below. Track coverage, premiums, and renewal dates.
A5: HEALTH INSURANCE POLICIES
A6: Policy Name | B6: Insurer Name | C6: Policy Number | D6: Coverage Amount (₹) | E6: Annual Premium (₹) | F6: Renewal Date (DD-MM-YYYY) | G6: Days Until Renewal | H6: Type | I6: Sum Insured Status | J6: Claim History
A7: Family Health Plan | B7: HDFC ERGO | C7: POL-2023-HLT-001 | D7: 500000 | E7: 15000 | F7: 2026-03-15 | G7: =DAYS('2026-03-15',TODAY()) -> 0 | H7: Comprehensive | I7: Active | J7: 0 claims
A8: ICICI Individual Health | B8: ICICI Lombard | C8: POL-2024-HLT-002 | D8: 750000 | E8: 18000 | F8: 2026-05-20 | G8: =DAYS('2026-05-20',TODAY()) -> 0 | H8: Comprehensive | I8: Active | J8: 1 claim
A9: Star Health Senior Plan | B9: Star Health | C9: POL-2023-HLT-003 | D9: 300000 | E9: 8000 | F9: 2026-02-28 | G9: =DAYS('2026-02-28',TODAY()) -> 0 | H9: Senior Citizen | I9: Active | J9: 0 claims
A10: Aditya Birla Health | B10: Aditya Birla Insurance | C10: POL-2024-HLT-004 | D10: 600000 | E10: 16000 | F10: 2026-04-10 | G10: =DAYS('2026-04-10',TODAY()) -> 0 | H10: Comprehensive | I10: Active | J10: 0 claims
A11: Apollo Health Advance | B11: Apollo Insurance | C11: POL-2023-HLT-005 | D11: 400000 | E11: 12000 | F11: 2026-01-30 | G11: =DAYS('2026-01-30',TODAY()) -> 0 | H11: Comprehensive | I11: Active | J11: 2 claims
A13: TERM LIFE INSURANCE POLICIES
A14: Policy Name | B14: Insurer Name | C14: Policy Number | D14: Sum Assured (₹) | E14: Annual Premium (₹) | F14: Maturity Date (DD-MM-YYYY) | G14: Days Until Renewal | H14: Coverage Duration | I14: Rider Coverage | J14: Status
A15: HDFC Life Term Plan | B15: HDFC Life | C15: POL-2023-TRM-001 | D15: 1000000 | E15: 8500 | F15: 2043-01-15 | G15: =DAYS('2043-01-15',TODAY()) -> 0 | H15: 20 years | I15: Accidental Rider | J15: Active
A16: SBI Life Term Plan | B16: SBI Life | C16: POL-2024-TRM-002 | D16: 1500000 | E16: 10500 | F16: 2044-06-20 | G16: =DAYS('2044-06-20',TODAY()) -> 0 | H16: 20 years | I16: Critical Illness | J16: Active
A17: LIC Term Plan 2026 | B17: LIC | C17: POL-2023-TRM-003 | D17: 2000000 | E17: 14000 | F17: 2043-12-05 | G17: =DAYS('2043-12-05',TODAY()) -> 0 | H17: 20 years | I17: Waiver of Premium | J17: Active
A18: Bajaj Allianz Term | B18: Bajaj Allianz | C18: POL-2024-TRM-004 | D18: 1200000 | E18: 9500 | F18: 2044-03-10 | G18: =DAYS('2044-03-10',TODAY()) -> 0 | H18: 20 years | I18: Accidental Rider | J18: Active
A19: Max Life Term Plan | B19: Max Life | C19: POL-2023-TRM-005 | D19: 1800000 | E19: 12000 | F19: 2043-08-22 | G19: =DAYS('2043-08-22',TODAY()) -> 0 | H19: 20 years | I19: Critical Illness + Accidental | J19: Active
A21: MOTOR INSURANCE POLICIES
A22: Vehicle Name | B22: Insurer Name | C22: Policy Number | D22: Registration Number | E22: Coverage Amount (₹) | F22: Annual Premium (₹) | G22: Renewal Date (DD-MM-YYYY) | H22: Days Until Renewal | I22: Policy Type | J22: NCB %
A23: Honda City (2022) | B23: Bajaj Allianz | C23: POL-2023-MTR-001 | D23: AP-05-XY-1234 | E23: 1200000 | F23: 8500 | G23: 2026-06-15 | H23: =DAYS('2026-06-15',TODAY()) -> 0 | I23: Comprehensive | J23: 20%
A24: Toyota Fortuner (2020) | B24: ICICI Lombard | C24: POL-2023-MTR-002 | D24: AP-05-XY-5678 | E24: 1500000 | F24: 12000 | G24: 2026-07-20 | H24: =DAYS('2026-07-20',TODAY()) -> 0 | I24: Comprehensive | J24: 35%
A25: Maruti Swift (2018) | B25: National Insurance | C25: POL-2024-MTR-003 | D25: AP-05-XY-9012 | E25: 800000 | F25: 6500 | G25: 2026-03-10 | H25: =DAYS('2026-03-10',TODAY()) -> 0 | I25: Comprehensive | J25: 50%
A26: Scooty (2019) | B26: Royal Sundaram | C26: POL-2024-MTR-004 | D26: AP-05-XY-3456 | E26: 400000 | F26: 2500 | G26: 2026-02-28 | H26: =DAYS('2026-02-28',TODAY()) -> 0 | I26: Comprehensive | J26: 45%
A27: Activa (2021) | B27: New India | C27: POL-2023-MTR-005 | D27: AP-05-XY-7890 | E27: 350000 | F27: 2200 | G27: 2026-05-15 | H27: =DAYS('2026-05-15',TODAY()) -> 0 | I27: Comprehensive | J27: 25%
A29: HOME INSURANCE POLICIES
A30: Policy Name | B30: Insurer Name | C30: Policy Number | D30: Property Value (₹) | E30: Coverage Amount (₹) | F30: Annual Premium (₹) | G30: Renewal Date (DD-MM-YYYY) | H30: Days Until Renewal | I30: Coverage Type | J30: Claim History
A31: Home & Building Insurance | B31: HDFC ERGO | C31: POL-2023-HOM-001 | D31: 5000000 | E31: 3500000 | F31: 18000 | G31: 2026-08-15 | H31: =DAYS('2026-08-15',TODAY()) -> 0 | I31: Comprehensive | J31: 0 claims
A32: Apartment/Flat Coverage | B32: Bajaj Allianz | C32: POL-2024-HOM-002 | D32: 3000000 | E32: 2000000 | F32: 12000 | G32: 2026-04-20 | H32: =DAYS('2026-04-20',TODAY()) -> 0 | I32: Standard | J32: 0 claims
A33: Landlord Insurance | B33: New India | C33: POL-2023-HOM-003 | D33: 4000000 | E33: 2500000 | F33: 14000 | G33: 2026-09-10 | H33: =DAYS('2026-09-10',TODAY()) -> 0 | I33: Comprehensive | J33: 1 claim
A34: Contents Insurance | B34: Royal Sundaram | C34: POL-2024-HOM-004 | D34: 1500000 | E34: 1000000 | F34: 8000 | G34: 2026-06-05 | H34: =DAYS('2026-06-05',TODAY()) -> 0 | I34: Standard | J34: 0 claims
A35: Commercial Property Coverage | B35: Oriental Insurance | C35: POL-2023-HOM-005 | D35: 2000000 | E35: 1500000 | F35: 10000 | G35: 2026-03-30 | H35: =DAYS('2026-03-30',TODAY()) -> 0 | I35: Comprehensive | J35: 0 claims
A37: PERSONAL ACCIDENT POLICIES
A38: Policy Name | B38: Insurer Name | C38: Policy Number | D38: Coverage Amount (₹) | E38: Annual Premium (₹) | F38: Renewal Date (DD-MM-YYYY) | G38: Days Until Renewal | H38: Type | I38: Death Benefit | J38: Disability Benefit
A39: Individual PA Insurance | B39: National Insurance | C39: POL-2024-PAC-001 | D39: 250000 | E39: 2500 | F39: 2026-02-15 | G39: =DAYS('2026-02-15',TODAY()) -> 0 | H39: Individual | I39: 250000 | J39: ₹500/day
A40: Family PA Plan | B40: LIC | C40: POL-2023-PAC-002 | D40: 300000 | E40: 3000 | F40: 2026-04-20 | G40: =DAYS('2026-04-20',TODAY()) -> 0 | H40: Family | I40: 300000 | J40: ₹600/day
A41: Professional PA Rider | B41: Max Life | C41: POL-2024-PAC-003 | D41: 500000 | E41: 5000 | F41: 2026-07-10 | G41: =DAYS('2026-07-10',TODAY()) -> 0 | H41: Professional | I41: 500000 | J41: ₹1000/day
A42: Sports/Adventure PA | B42: HDFC Life | C42: POL-2023-PAC-004 | D42: 150000 | E42: 1500 | F42: 2026-05-05 | G42: =DAYS('2026-05-05',TODAY()) -> 0 | H42: Sports | I42: 150000 | J42: ₹300/day
A43: Student Travel PA | B43: Bajaj Allianz | C43: POL-2024-PAC-005 | D43: 200000 | E43: 1200 | F43: 2026-06-30 | G43: =DAYS('2026-06-30',TODAY()) -> 0 | H43: Travel | I43: 200000 | J43: ₹400/day
A45: POLICY SUMMARY
A46: Total Policies Active | B46: =COUNTA(A7:A31) -> 0
A47: Total Annual Premium | B47: =SUM(E7:E31) -> 0
...

Sheet Coverage Calculator
A1: INSURANCE COVERAGE CALCULATOR - DETERMINE YOUR NEEDS
A3: Calculate the right insurance coverage based on your age, income, and financial obligations.
A5: HEALTH INSURANCE CALCULATOR
A6: Factor | B6: Your Value | C6: Calculation | D6: Result | E6: Notes
A7: Annual Income | B7: ₹1500000 | C7: Your gross annual income | E7: Enter your annual income
A8: Family Members | B8: 4 | C8: No. of dependents | E8: Include all family members
A9: Age (Youngest) | B9: 2 | C9: Age of youngest member | E9: For rider calculation
A10: Age (Oldest) | B10: 65 | C10: Age of oldest member | E10: May affect premium
A12: HEALTH INSURANCE CALCULATION
A13: Requirement Type | B13: Formula | C13: Recommended Amount (₹) | D13: Your Coverage (₹) | E13: Gap (₹)
A14: Individual Adult | B14: Age*10000 + 50000 | C14: =IF(B7<30,300000,IF(B7<40,400000,IF(B7<50,500000,600000))) -> 0 | D14: 500000 | E14: =MAX(0,B24-D24) -> 0
A15: Family Coverage | B15: No. of members * 5-10L | C15: =(B8*500000) -> 0 | D15: =2500000 -> 0 | E15: =MAX(0,B25-D25) -> 0
A16: Critical Illness Rider | B16: 1/5 of base coverage | C16: =B24/5 -> 0 | D16: =100000 -> 0 | E16: =MAX(0,B26-D26) -> 0
A17: Accidental Coverage | B17: 1/2 of base coverage | C17: =B24/2 -> 0 | D17: =250000 -> 0 | E17: =MAX(0,B27-D27) -> 0
A18: Recommended Total | B18: Sum of above needs | C18: =B24+B25 -> 0 | D18: =2600000 -> 0 | E18: =MAX(0,B28-D28) -> 0
A20: TERM LIFE INSURANCE CALCULATOR
A21: Factor | B21: Your Value | C21: Calculation | D21: Result | E21: Notes
A22: Annual Income | B22: ₹1500000 | C22: Your gross annual income
A23: Number of Dependents | B23: 2 | C23: People dependent on you
A24: Home Loan Outstanding | B24: ₹2000000 | C24: Remaining home loan balance | E24: Must be paid off
A25: Education Loan | B25: ₹500000 | C25: Remaining education loan
A26: Other Liabilities | B26: ₹300000 | C26: Other personal debts
A27: Spouse Income | B27: ₹800000 | C27: Spouse's annual income | E27: Add if available
A28: Years to Retirement | B28: 25 | C28: Estimated retirement age
A30: TERM LIFE CALCULATION
A31: Calculation Method | B31: Formula | C31: Recommended Amount (₹) | D31: Notes
A32: 10x Income Rule | B32: Annual Income * 10 | C32: =(B37*10) -> 0 | D32: Conservative approach
A33: Human Life Value | B33: (Income * Years) - Liabilities | C33: =((B37*B43)-SUM(B39:B42)) -> 0 | D33: Adjusted for loans
A34: Income Replacement (20 years) | B34: (Income * 20) - Liabilities | C34: =((B37*20)-SUM(B39:B42)) -> 0 | D34: Family financial security
A35: Max Recommended | B35: Whichever is highest | C35: =MAX(B45,B46,B47) -> 0 | D35: Safe coverage limit
A36: Your Current Coverage | B36: ₹6500000 | C36: From policy tracker
A37: Coverage Gap | B37: =MAX(0,B49-B50) -> 0 | C37: Need to purchase
A38: Recommended Action | B38: =IF(B49>B50,"Increase","Adequate") -> 0
A40: MOTOR INSURANCE CALCULATOR
A41: Factor | B41: Your Value | C41: Calculation | D41: Result | E41: Notes
A42: Vehicle 1 Value | B42: ₹800000 | C42: Current market value
A43: Vehicle 2 Value | B43: ₹1500000 | C43: Current market value
A44: Annual Mileage | B44: 15000 | C44: Km driven per year
A45: Driving History (Years) | B45: 5 | C45: Years of driving experience
A46: Claims in Last 3 Years | B46: 0 | C46: Number of claims made
...

Sheet Renewal Alerts
A1: INSURANCE RENEWAL ALERTS & REMINDERS
A3: Stay on top of your policy renewals with automated reminders and tracking.
A5: RENEWAL SCHEDULE (NEXT 12 MONTHS)
A6: Month | B6: Policy Name | C6: Insurance Type | D6: Renewal Date | E6: Days Until Renewal | F6: Annual Premium (₹) | G6: Action Status
A7: January 2026 | B7: Apollo Health Advance | C7: Health | D7: 2026-01-30 | E7: 28 | F7: 12000 | G7: ❗ URGENT
A8: February 2026 | B8: Star Health Senior Plan | C8: Health | D8: 2026-02-28 | E8: 57 | F8: 8000 | G8: ⚠️ Review Soon
A9: February 2026 | B9: Individual PA Insurance | C9: Personal Accident | D9: 2026-02-15 | E9: 44 | F9: 2500 | G9: ⚠️ Review Soon
A10: February 2026 | B10: Scooty Motor Insurance | C10: Motor | D10: 2026-02-28 | E10: 57 | F10: 2200 | G10: ⚠️ Review Soon
A11: March 2026 | B11: Family Health Plan | C11: Health | D11: 2026-03-15 | E11: 72 | F11: 15000 | G11: Plan renewal
A12: March 2026 | B12: Honda City Motor Insurance | C12: Motor | D12: 2026-03-10 | E12: 67 | F12: 8500 | G12: Plan renewal
A13: March 2026 | B13: Commercial Property | C13: Home | D13: 2026-03-30 | E13: 87 | F13: 10000 | G13: Plan renewal
A14: April 2026 | B14: ICICI Individual Health | C14: Health | D14: 2026-04-20 | E14: 108 | F14: 18000 | G14: Early planning
A15: April 2026 | B15: Aditya Birla Health | C15: Health | D15: 2026-04-10 | E15: 98 | F15: 16000 | G15: Early planning
A16: April 2026 | B16: Family PA Plan | C16: Personal Accident | D16: 2026-04-20 | E16: 108 | F16: 3000 | G16: Early planning
A17: April 2026 | B17: Apartment/Flat Coverage | C17: Home | D17: 2026-04-20 | E17: 108 | F17: 12000 | G17: Early planning
... A22: June 2026 | B22: Home & Building Insurance | C22: Home | D22: 2026-08-15 | E22: 225 | F22: 18000 | G22: Plan ahead
A24: URGENT RENEWALS (NEXT 30 DAYS)
A25: Policy Name | B25: Insurance Type | C25: Renewal Date | D25: Days Left | E25: Current Premium | F25: Action Required | G25: Status
A26: Apollo Health Advance | B26: Health Insurance | C26: 2026-01-30 | D26: 28 | E26: 12000 | F26: Renew immediately | G26: CRITICAL
A28: RENEWAL PLANNING (30-90 DAYS)
A29: Policy Name | B29: Insurance Type | C29: Renewal Date | D29: Days Left | E29: Current Premium | F29: Review Points | G29: Task
A30: Star Health Senior Plan | B30: Health Insurance | C30: 2026-02-28 | D30: 57 | E30: 8000 | F30: Review coverage & claims | G30: Compare quotes
A31: Individual PA Insurance | B31: Personal Accident | C31: 2026-02-15 | D31: 44 | E31: 2500 | F31: Check disability limits | G31: Renew early
A32: Scooty Motor Insurance | B32: Motor Insurance | C32: 2026-02-28 | D32: 57 | E32: 2200 | F32: NCB (45%) can be increased | G32: Claim NCB
A33: Family Health Plan | B33: Health Insurance | C33: 2026-03-15 | D33: 72 | E33: 15000 | F33: Update beneficiaries | G33: Add riders
A34: Honda City Motor Insurance | B34: Motor Insurance | C34: 2026-03-10 | D34: 67 | E34: 8500 | F34: Claim 20% NCB | G34: Renew early
A35: Commercial Property | B35: Home Insurance | C35: 2026-03-30 | D35: 87 | E35: 10000 | F35: Property appreciation value | G35: Increase coverage
A37: RENEWAL REMINDERS CHECKLIST
A38: Policy | B38: 30-Day Prior | C38: 15-Day Prior | D38: 7-Day Prior | E38: Day Of | F38: After Renewal
A39: Health Insurance | B39: Compare quotes & plans | C39: Final decision & approval | D39: Payment arrangement | E39: Complete payment | F39: Update records
A40: Term Life Insurance | B40: Review coverage needs | C40: Check for riders needed | D40: Final decision | E40: Complete payment | F40: Store policy
A41: Motor Insurance | B41: Get no claim bonus cert | C41: Compare quotes online | D41: Arrange vehicle docs | E41: Complete payment | F41: Update with RTO
A42: Home Insurance | B42: Review property value | C42: Check claim history | D42: Final decision | E42: Complete payment | F42: Update beneficiary
A43: Personal Accident | B43: Assess risk changes | C43: Compare options | D43: Final decision | E43: Complete payment | F43: Update coverage
A45: RENEWAL COST TRACKER
A46: Policy Type | B46: Current Premium (₹) | C46: Expected Increase | D46: New Premium (₹) | E46: Savings Opportunity (₹) | F46: Action
A47: Health Insurance (Family) | B47: 15000 | C47: 5-10% | D47: =B54*1.075 -> 0 | E47: Compare 2-3 quotes | F47: Switch if better
A48: Term Life Insurance | B48: 10500 | C48: 2-3% | D48: =B55*1.025 -> 0 | E48: Loyalty benefit available | F48: Negotiate with insurer
A49: Motor Insurance - Car 1 | B49: 8500 | C49: 5-10% | D49: =B56*1.075 -> 0 | E49: Claim higher NCB | F49: Switch insurer
A50: Home Insurance | B50: 18000 | C50: 8-15% | D50: =B57*1.10 -> 0 | E50: Bundle discount possible | F50: Review add-ons
...

Sheet Premium Tracker
A1: INSURANCE PREMIUM TRACKER & BUDGET PLANNING
A3: Track all insurance premiums, plan quarterly budgets, and identify savings opportunities.
A5: ANNUAL PREMIUM SUMMARY
A6: Insurance Type | B6: Number of Policies | C6: Total Annual Premium (₹) | D6: Avg Premium per Policy (₹) | E6: % of Annual Budget | F6: Trend
A7: Health Insurance | B7: 5 | C7: =SUM('Policy Tracker'!E7:E11) -> 0 | D7: =E8/D8 -> 0 | E7: =E8/SUM($E$8:$E$12)*100% -> 0 | F7: Up 8%
A8: Term Life Insurance | B8: 5 | C8: =SUM('Policy Tracker'!E12:E16) -> 0 | D8: =E9/D9 -> 0 | E8: =E9/SUM($E$8:$E$12)*100% -> 0 | F8: Stable
A9: Motor Insurance | B9: 5 | C9: =SUM('Policy Tracker'!E17:E21) -> 0 | D9: =E10/D10 -> 0 | E9: =E10/SUM($E$8:$E$12)*100% -> 0 | F9: Down 5%
A10: Home Insurance | B10: 5 | C10: =SUM('Policy Tracker'!E22:E26) -> 0 | D10: =E11/D11 -> 0 | E10: =E11/SUM($E$8:$E$12)*100% -> 0 | F10: Up 3%
A11: Personal Accident | B11: 5 | C11: =SUM('Policy Tracker'!E27:E31) -> 0 | D11: =E12/D12 -> 0 | E11: =E12/SUM($E$8:$E$12)*100% -> 0 | F11: Stable
A12: TOTAL ANNUAL | B12: 25 | C12: =SUM(E8:E12) -> 0 | D12: =E13/D13 -> 0 | E12: 100% | F12: Avg
A14: QUARTERLY PREMIUM BREAKDOWN
A15: Quarter | B15: Health (₹) | C15: Life (₹) | D15: Motor (₹) | E15: Home (₹) | F15: Personal Accident (₹) | G15: Total (₹)
A16: Q1 (Jan-Mar) | B16: =E8/4 -> 0 | C16: =E9/4 -> 0 | D16: =E10/4 -> 0 | E16: =E11/4 -> 0 | F16: =E12/4 -> 0 | G16: =SUM(B20:F20) -> 0
A17: Q2 (Apr-Jun) | B17: =E8/4 -> 0 | C17: =E9/4 -> 0 | D17: =E10/4 -> 0 | E17: =E11/4 -> 0 | F17: =E12/4 -> 0 | G17: =SUM(B21:F21) -> 0
A18: Q3 (Jul-Sep) | B18: =E8/4 -> 0 | C18: =E9/4 -> 0 | D18: =E10/4 -> 0 | E18: =E11/4 -> 0 | F18: =E12/4 -> 0 | G18: =SUM(B22:F22) -> 0
A19: Q4 (Oct-Dec) | B19: =E8/4 -> 0 | C19: =E9/4 -> 0 | D19: =E10/4 -> 0 | E19: =E11/4 -> 0 | F19: =E12/4 -> 0 | G19: =SUM(B23:F23) -> 0
A20: Annual Total | B20: =SUM(B20:B23) -> 0 | C20: =SUM(C20:C23) -> 0 | D20: =SUM(D20:D23) -> 0 | E20: =SUM(E20:E23) -> 0 | F20: =SUM(F20:F23) -> 0 | G20: =SUM(G20:G23) -> 0
A22: MONTHLY BUDGET ALLOCATION
A23: Month | B23: Fixed Premium (₹) | C23: Variable Premium (₹) | D23: Total Needed (₹) | E23: Monthly Savings Plan (₹) | F23: Status
A24: January | B24: =E13/12 -> 0 | C24: 12000 | D24: =B28+C28 -> 0 | E24: =D28 -> 0
A25: February | B25: =E13/12 -> 0 | C25: 8000 | D25: =B29+C29 -> 0 | E25: =D29 -> 0
A26: March | B26: =E13/12 -> 0 | C26: 18000 | D26: =B30+C30 -> 0 | E26: =D30 -> 0
A27: April | B27: =E13/12 -> 0 | C27: 16000 | D27: =B31+C31 -> 0 | E27: =D31 -> 0
A28: May | B28: =E13/12 -> 0 | C28: 15000 | D28: =B32+C32 -> 0 | E28: =D32 -> 0
A29: June | B29: =E13/12 -> 0 | C29: 12000 | D29: =B33+C33 -> 0 | E29: =D33 -> 0
A30: July | B30: =E13/12 -> 0 | C30: 8000 | D30: =B34+C34 -> 0 | E30: =D34 -> 0
A31: August | B31: =E13/12 -> 0 | C31: 0 | D31: =B35+C35 -> 0 | E31: =D35 -> 0
A32: September | B32: =E13/12 -> 0 | C32: 0 | D32: =B36+C36 -> 0 | E32: =D36 -> 0
A33: October | B33: =E13/12 -> 0 | C33: 0 | D33: =B37+C37 -> 0 | E33: =D37 -> 0
A34: November | B34: =E13/12 -> 0 | C34: 5000 | D34: =B38+C38 -> 0 | E34: =D38 -> 0
A35: December | B35: =E13/12 -> 0 | C35: 2000 | D35: =B39+C39 -> 0 | E35: =D39 -> 0
A36: Total | B36: =SUM(B28:B39) -> 0 | C36: =SUM(C28:C39) -> 0 | D36: =SUM(D28:D39) -> 0 | E36: =SUM(E28:E39) -> 0
A38: PREMIUM YEAR-ON-YEAR COMPARISON
A39: Insurance Type | B39: 2023 Annual (₹) | C39: 2024 Annual (₹) | D39: 2025 Annual (₹) | E39: YoY Change 2024 | F39: YoY Change 2025
A40: Health Insurance | B40: 65000 | C40: 72000 | D40: 69000 | E40: +10.8% | F40: -4.2%
A41: Term Life Insurance | B41: 45000 | C41: 47000 | D41: 52500 | E41: +4.4% | F41: +11.7%
A42: Motor Insurance | B42: 32000 | C42: 32500 | D42: 31200 | E42: +1.6% | F42: -4.0%
A43: Home Insurance | B43: 48000 | C43: 52000 | D43: 54000 | E43: +8.3% | F43: +3.8%
A44: Personal Accident | B44: 10500 | C44: 11000 | D44: 11700 | E44: +4.8% | F44: +6.4%
A45: TOTAL ANNUAL | B45: 200500 | C45: 214500 | D45: 218400 | E45: +6.9% | F45: +1.8%
...
