Workbook

Sheet Dashboard
A1: INVESTMENT PORTFOLIO MANAGER - VISUAL DASHBOARD
A3: YOUR PORTFOLIO OVERVIEW
A4: Total Portfolio Value | B4: ₹ | C4: =SUM('Investments'!E6:E24) -> 0 | E4: Current market value
A5: Total Invested Amount | B5: ₹ | C5: =SUM('Investments'!D6:D24) -> 0 | E5: Total money put in
A6: Total Gain/Loss | B6: ₹ | C6: =B3-B4 -> 0 | E6: Profit or loss
A7: Overall Return % | C7: =(B5/B4)*100% -> 0 | E7: Return on investment
A9: PORTFOLIO RETURNS ANALYSIS
A10: Return Type | B10: Amount (₹) | C10: Percentage | D10: Annualized | E10: Performance
A11: Absolute Return | B11: =B5 -> 0 | C11: =B6 -> 0 | D11: =IF(YEAR(TODAY())-YEAR('Investments'!C6)=0,B6,(B6/(YEAR(TODAY())-YEAR('Investments'!C6)))*100)% -> 0 | E11: Overall gain
A12: CAGR (Compounded Annual) | B12: =B5 -> 0 | C12: =IF(YEAR(TODAY())-YEAR('Investments'!C6)=0,0,((POWER((B3/B4),(1/(YEAR(TODAY())-YEAR('Investments'!C6))))-1)*100)% -> 0 | D12: =IF(YEAR(TODAY())-YEAR('Investments'!C6)=0,"<1 year","Calculated")% -> 0 | E12: Per year avg
A13: YTD (This Year) Return | B13: =B5*0.45 -> 0 | C13: 45% | D13: 2026 performance | E13: Current year
A15: ASSET ALLOCATION BREAKDOWN
A16: Asset Class | B16: Invested (₹) | C16: Current Value (₹) | D16: % of Portfolio | E16: Status
A17: Mutual Funds (Equity) | B17: =SUMIF('Investments'!C6:C24,"Equity MF",'Investments'!D6:D24) -> 0 | C17: =SUMIF('Investments'!C6:C24,"Equity MF",'Investments'!E6:E24) -> 0 | D17: =SUMIF('Investments'!C6:C24,"Equity MF",'Investments'!E6:E24)/B3 -> 0 | E17: Growth focus
A18: Mutual Funds (Debt) | B18: =SUMIF('Investments'!C6:C24,"Debt MF",'Investments'!D6:D24) -> 0 | C18: =SUMIF('Investments'!C6:C24,"Debt MF",'Investments'!E6:E24) -> 0 | D18: =SUMIF('Investments'!C6:C24,"Debt MF",'Investments'!E6:E24)/B3 -> 0 | E18: Stable focus
A19: Mutual Funds (Hybrid) | B19: =SUMIF('Investments'!C6:C24,"Hybrid MF",'Investments'!D6:D24) -> 0 | C19: =SUMIF('Investments'!C6:C24,"Hybrid MF",'Investments'!E6:E24) -> 0 | D19: =SUMIF('Investments'!C6:C24,"Hybrid MF",'Investments'!E6:E24)/B3 -> 0 | E19: Balanced
A20: Stocks (Direct) | B20: =SUMIF('Investments'!C6:C24,"Stocks",'Investments'!D6:D24) -> 0 | C20: =SUMIF('Investments'!C6:C24,"Stocks",'Investments'!E6:E24) -> 0 | D20: =SUMIF('Investments'!C6:C24,"Stocks",'Investments'!E6:E24)/B3 -> 0 | E20: High risk
A21: Fixed Deposits | B21: =SUMIF('Investments'!C6:C24,"FD",'Investments'!D6:D24) -> 0 | C21: =SUMIF('Investments'!C6:C24,"FD",'Investments'!E6:E24) -> 0 | D21: =SUMIF('Investments'!C6:C24,"FD",'Investments'!E6:E24)/B3 -> 0 | E21: Low risk
A22: PPF | B22: =SUMIF('Investments'!C6:C24,"PPF",'Investments'!D6:D24) -> 0 | C22: =SUMIF('Investments'!C6:C24,"PPF",'Investments'!E6:E24) -> 0 | D22: =SUMIF('Investments'!C6:C24,"PPF",'Investments'!E6:E24)/B3 -> 0 | E22: Safe
A23: NPS | B23: =SUMIF('Investments'!C6:C24,"NPS",'Investments'!D6:D24) -> 0 | C23: =SUMIF('Investments'!C6:C24,"NPS",'Investments'!E6:E24) -> 0 | D23: =SUMIF('Investments'!C6:C24,"NPS",'Investments'!E6:E24)/B3 -> 0 | E23: Retirement
A24: Gold/Silver | B24: =SUMIF('Investments'!C6:C24,"Gold/Silver",'Investments'!D6:D24) -> 0 | C24: =SUMIF('Investments'!C6:C24,"Gold/Silver",'Investments'!E6:E24) -> 0 | D24: =SUMIF('Investments'!C6:C24,"Gold/Silver",'Investments'!E6:E24)/B3 -> 0 | E24: Hedge
A26: ALLOCATION TARGETS vs ACTUAL
A27: Asset Class | B27: Target Allocation | C27: Current Allocation | D27: Difference | E27: Recommendation
A28: Equity (MF + Stocks) | B28: 60% | C28: =SUMIF('Investments'!C6:C24,"Equity MF",'Investments'!E6:E24)/B3+SUMIF('Investments'!C6:C24,"Stocks",'Investments'!E6:E24)/B3 -> 0 | D28: =E32-D32 -> 0 | E28: =IF(E32>D32,"Reduce","Increase") -> 0
A29: Debt (MF + FD) | B29: 25% | C29: =SUMIF('Investments'!C6:C24,"Debt MF",'Investments'!E6:E24)/B3+SUMIF('Investments'!C6:C24,"FD",'Investments'!E6:E24)/B3 -> 0 | D29: =E33-D33 -> 0 | E29: =IF(E33>D33,"Reduce","Increase") -> 0
A30: Retirement (NPS) | B30: 10% | C30: =SUMIF('Investments'!C6:C24,"NPS",'Investments'!E6:E24)/B3 -> 0 | D30: =E34-D34 -> 0 | E30: =IF(E34>D34,"Reduce","Increase") -> 0
A31: Safe Haven (PPF, Gold) | B31: 5% | C31: =SUMIF('Investments'!C6:C24,"PPF",'Investments'!E6:E24)/B3+SUMIF('Investments'!C6:C24,"Gold/Silver",'Investments'!E6:E24)/B3 -> 0 | D31: =E35-D35 -> 0 | E31: =IF(E35>D35,"Reduce","Increase") -> 0
A33: TOP 5 PERFORMERS
A34: Rank | B34: Investment Name | C34: Current Value (₹) | D34: Gain/Loss (₹) | E34: Return %
A35: 1 | B35: Best performer | C35: =LARGE('Investments'!E6:E24,1) -> 0 | D35: =LARGE('Investments'!F6:F24,1) -> 0 | E35: =LARGE('Investments'!G6:G24,1)% -> 0
A36: 2 | B36: Second best | C36: =LARGE('Investments'!E6:E24,2) -> 0 | D36: =LARGE('Investments'!F6:F24,2) -> 0 | E36: =LARGE('Investments'!G6:G24,2)% -> 0
A37: 3 | B37: Third best | C37: =LARGE('Investments'!E6:E24,3) -> 0 | D37: =LARGE('Investments'!F6:F24,3) -> 0 | E37: =LARGE('Investments'!G6:G24,3)% -> 0
A38: 4 | B38: Fourth | C38: =LARGE('Investments'!E6:E24,4) -> 0 | D38: =LARGE('Investments'!F6:F24,4) -> 0 | E38: =LARGE('Investments'!G6:G24,4)% -> 0
A39: 5 | B39: Fifth | C39: =LARGE('Investments'!E6:E24,5) -> 0 | D39: =LARGE('Investments'!F6:F24,5) -> 0 | E39: =LARGE('Investments'!G6:G24,5)% -> 0
A41: QUICK INSIGHTS
A42: Number of Investments | B42: =COUNTA('Investments'!A6:A24) -> 0 | C42: Active holdings
A43: Average Return per Investment | B43: =AVERAGE('Investments'!G6:G24)% -> 0 | C43: Across portfolio
A44: Best Performing Asset Class | B44: =INDEX('Investments'!C6:C24,MATCH(MAX('Investments'!G6:G24),'Investments'!G6:G24,0)) -> 0 | C44: Top class
A45: Lowest Performing Asset | B45: =INDEX('Investments'!A6:A24,MATCH(MIN('Investments'!G6:G24),'Investments'!G6:G24,0)) -> 0 | C45: Bottom investment
A46: Portfolio Risk Level | B46: =IF(SUMIF('Investments'!C6:C24,"Equity MF",'Investments'!E6:E24)/B3>0.60,"HIGH RISK",IF(SUMIF('Investments'!C6:C24,"Equity MF",'Investments'!E6:E24)/B3>0.40,"MODERATE RISK","LOW RISK")) -> 0 | C46: Based on equity %

Sheet Investments
A1: INVESTMENT PORTFOLIO - TRACK ALL INVESTMENTS
A3: Add all your investments below. System auto-calculates returns.
A5: Investment Details
A6: Investment Name | B6: Asset Type | C6: Investment Date | D6: Amount Invested (₹) | E6: Current Value (₹) | F6: Gain/Loss (₹) | G6: Return % | H6: Annualized Return (CAGR)
A7: HDFC Equity Fund | B7: Equity MF | C7: 2023-01-15 | D7: 100000 | E7: 125000 | F7: =E6-D6 -> 0 | G7: =(F6/D6)*100% -> 0 | H7: =(((E6/D6)^(1/(YEAR(TODAY())-YEAR(C6))))-1)*100% -> 0
A8: Axis Bank Ltd | B8: Stocks | C8: 2023-06-01 | D8: 50000 | E8: 62000 | F8: =E7-D7 -> 0 | G8: =(F7/D7)*100% -> 0 | H8: =(((E7/D7)^(1/(YEAR(TODAY())-YEAR(C7))))-1)*100% -> 0
A9: ICICI Prudential PPF | B9: PPF | C9: 2022-01-01 | D9: 150000 | E9: 185000 | F9: =E8-D8 -> 0 | G9: =(F8/D8)*100% -> 0 | H9: =(((E8/D8)^(1/(YEAR(TODAY())-YEAR(C8))))-1)*100% -> 0
A10: State Bank FD (5 Year) | B10: FD | C10: 2023-03-10 | D10: 200000 | E10: 225000 | F10: =E9-D9 -> 0 | G10: =(F9/D9)*100% -> 0 | H10: =(((E9/D9)^(1/(YEAR(TODAY())-YEAR(C9))))-1)*100% -> 0
A11: ELSS Tax Saver | B11: Equity MF | C11: 2024-01-01 | D11: 50000 | E11: 54000 | F11: =E10-D10 -> 0 | G11: =(F10/D10)*100% -> 0 | H11: =(((E10/D10)^(1/(YEAR(TODAY())-YEAR(C10))))-1)*100% -> 0
A12: HDFC Bank NPS | B12: NPS | C12: 2023-02-01 | D12: 120000 | E12: 138000 | F12: =E11-D11 -> 0 | G12: =(F11/D11)*100% -> 0 | H12: =(((E11/D11)^(1/(YEAR(TODAY())-YEAR(C11))))-1)*100% -> 0
A13: Debt Fund (Low Risk) | B13: Debt MF | C13: 2024-06-15 | D13: 75000 | E13: 77500 | F13: =E12-D12 -> 0 | G13: =(F12/D12)*100% -> 0 | H13: =(((E12/D12)^(1/(YEAR(TODAY())-YEAR(C12))))-1)*100% -> 0
A14: Gold ETF | B14: Gold/Silver | C14: 2023-09-20 | D14: 40000 | E14: 45000 | F14: =E13-D13 -> 0 | G14: =(F13/D13)*100% -> 0 | H14: =(((E13/D13)^(1/(YEAR(TODAY())-YEAR(C13))))-1)*100% -> 0
A15: Reliance Industries | B15: Stocks | C15: 2024-03-01 | D15: 80000 | E15: 88000 | F15: =E14-D14 -> 0 | G15: =(F14/D14)*100% -> 0 | H15: =(((E14/D14)^(1/(YEAR(TODAY())-YEAR(C14))))-1)*100% -> 0
A16: Hybrid Fund | B16: Hybrid MF | C16: 2023-11-10 | D16: 100000 | E16: 108000 | F16: =E15-D15 -> 0 | G16: =(F15/D15)*100% -> 0 | H16: =(((E15/D15)^(1/(YEAR(TODAY())-YEAR(C15))))-1)*100% -> 0
A17: Kotak Bank FD | B17: FD | C17: 2024-01-20 | D17: 100000 | E17: 103500 | F17: =E16-D16 -> 0 | G17: =(F16/D16)*100% -> 0 | H17: =(((E16/D16)^(1/(YEAR(TODAY())-YEAR(C16))))-1)*100% -> 0
A18: Infosys Ltd | B18: Stocks | C18: 2023-07-15 | D18: 60000 | E18: 72000 | F18: =E17-D17 -> 0 | G18: =(F17/D17)*100% -> 0 | H18: =(((E17/D17)^(1/(YEAR(TODAY())-YEAR(C17))))-1)*100% -> 0
... A25: SBI Liquid Fund | B25: Debt MF | C25: 2024-05-15 | D25: 50000 | E25: 50750 | F25: =E24-D24 -> 0 | G25: =(F24/D24)*100% -> 0 | H25: =(((E24/D24)^(1/(YEAR(TODAY())-YEAR(C24))))-1)*100% -> 0
A27: PORTFOLIO SUMMARY
A28: Total Invested | B28: ₹ | C28: =SUM(D6:D24) -> 0
A29: Total Current Value | B29: ₹ | C29: =SUM(E6:E24) -> 0
A30: Total Gain/Loss | B30: ₹ | C30: =SUM(F6:F24) -> 0
A31: Overall Return % | C31: =(SUM(F6:F24)/SUM(D6:D24))*100% -> 0
A32: Average CAGR | C32: =AVERAGE(H6:H24)% -> 0

Sheet Return Calculator
A1: RETURN CALCULATOR - ABSOLUTE & CAGR ANALYSIS
A3: Calculate different types of returns and understand your investment performance.
A5: INVESTMENT RETURNS EXPLAINED
A6: Return Type | B6: Formula | C6: Best For | D6: Time Factor | E6: Example
A7: Absolute Return | B7: (Current Value - Investment) / Investment × 100 | C7: Short-term (1-2 years) | D7: Does NOT consider time | E7: ₹100k → ₹120k = 20% in 1 month
A8: CAGR (Compounded Annual Growth Rate) | B8: ((Final Value / Initial)^(1/n) - 1) × 100 | C8: Medium to Long-term (3+ years) | D8: Considers compounding & time | E8: ₹100k → ₹150k over 3 years = 14.5% CAGR
A9: YTD (Year-to-Date) | B9: Current gain from Jan 1 to today | C9: Current year performance | D9: Partial year | E9: Jan 1 to now return
A11: CALCULATE YOUR RETURNS
A13: Your Investment Details | B13: Amount | C13: Enter Value | D13: Formula | E13: Result
A14: Investment Amount | B14: ₹ | C14: 100000 | D14: Starting amount
A15: Current Value | B15: ₹ | C15: 120000 | D15: Today's market value
A16: Investment Date | C16: 2023-01-01 | D16: When you invested
A17: Today's Date | C17: 2026-01-02 | D17: Current date
A19: ABSOLUTE RETURN CALCULATION
A20: Gain/Loss Amount | B20: ₹ | C20: =(D7-D6) -> 0 | D20: =D7-D6 -> 0
A21: Absolute Return % | C21: =((D7-D6)/D6)*100% -> 0 | D21: =((D7-D6)/D6)*100% -> 0 | E21: Simple return
A23: CAGR CALCULATION
A24: Years Invested | C24: =(YEAR(D10)-YEAR(D9)) -> 0 | D24: =YEAR(D10)-YEAR(D9) -> 0 | E24: 3 years
A25: CAGR % | C25: =((D7/D6)^(1/D12)-1)*100% -> 0 | D25: =((D7/D6)^(1/D12)-1)*100% -> 0 | E25: Per year growth
A27: COMPARISON: What CAGR Means
A28: Scenario | B28: Investment | C28: Value After 3 Years | D28: Absolute Return % | E28: CAGR | F28: Comparison
A29: Conservative | B29: ₹100,000 | C29: ₹115,000 | D29: 15% | E29: 4.8% CAGR | F29: Steady growth
A30: Moderate | B30: ₹100,000 | C30: ₹150,000 | D30: 50% | E30: 14.5% CAGR | F30: Good growth
A31: Aggressive | B31: ₹100,000 | C31: ₹200,000 | D31: 100% | E31: 26% CAGR | F31: High growth
A33: WHY CAGR MATTERS
A35: Issue with Absolute Return | B35: CAGR Solution | C35: Example | D35: Impact
A36: Ignores time invested | B36: Annualizes growth per year | C36: 100% return in 5 years looks huge, but CAGR shows it's only 15% yearly | D36: Prevents misleading comparisons
A37: Can't compare different timeframes | B37: Fair comparison across years | C37: Can't compare 1-year vs 5-year returns without CAGR | D37: Apples-to-apples comparison
A38: Doesn't show compounding effect | B38: Shows actual compound growth | C38: ₹100k at 20% abs. = not same as 20% every year | D38: Understand true growth
A40: REAL PORTFOLIO EXAMPLES
A42: EXAMPLE 1: Balanced Portfolio (3-Year Period)
A43: Investment | B43: Invested | C43: Current Value | D43: Absolute Return | E43: Time Period | F43: CAGR
A44: Equity MF | B44: ₹100,000 | C44: ₹145,000 | D44: 45% | E44: 3 years | F44: =((145000/100000)^(1/3)-1)*100% = 13.1% -> 0
A45: Debt MF | B45: ₹50,000 | C45: ₹55,000 | D45: 10% | E45: 3 years | F45: =((55000/50000)^(1/3)-1)*100% = 3.2% -> 0
A46: PPF | B46: ₹150,000 | C46: ₹185,000 | D46: 23.3% | E46: 3 years | F46: =((185000/150000)^(1/3)-1)*100% = 7.2% -> 0
A47: Total | B47: ₹300,000 | C47: ₹385,000 | D47: 28.3% | E47: 3 years | F47: =((385000/300000)^(1/3)-1)*100% = 8.2% CAGR -> 0
A49: EXAMPLE 2: Aggressive Portfolio (5-Year Period)
A50: Investment | B50: Invested | C50: Current Value | D50: Absolute Return | E50: Time Period | F50: CAGR
A51: Large Cap Equity | B51: ₹200,000 | C51: ₹380,000 | D51: 90% | E51: 5 years | F51: =((380000/200000)^(1/5)-1)*100% = 13.7% -> 0
A52: Mid Cap Equity | B52: ₹100,000 | C52: ₹190,000 | D52: 90% | E52: 5 years | F52: =((190000/100000)^(1/5)-1)*100% = 13.7% -> 0
...

Sheet Asset Allocation
A1: ASSET ALLOCATION & REBALANCING STRATEGY
A3: Optimize your portfolio with proper asset allocation based on age and goals.
A5: WHAT IS ASSET ALLOCATION?
A6: Concept | B6: Explanation | C6: Why It Matters | D6: Example
A7: Asset Allocation | B7: Dividing portfolio among different asset types (Equity, Debt, Gold, etc.) | C7: Different assets perform differently in different market conditions | D7: 60% Equity, 30% Debt, 10% Gold
A8: Diversification | B8: Spreading across multiple investments within each asset class | C8: Reduces risk of any single investment failing | D8: 5 stocks instead of 1
A9: Rebalancing | B9: Adjusting portfolio back to target allocation periodically | C9: Maintains risk level and forces buying low, selling high | D9: Quarterly or yearly review
A11: RECOMMENDED ALLOCATION BY AGE
A12: Age Group | B12: Equity % | C12: Debt % | D12: Gold/Safe % | E12: Risk Level | F12: Goal | G12: Example Portfolio
A13: 20-30 Years | B13: 70-80% | C13: 10-15% | D13: 5-10% | E13: High Risk | F13: Long-term growth | G13: ₹10L: ₹7.5L Equity, ₹1.5L Debt, ₹1L Gold
A14: 30-40 Years | B14: 60-70% | C14: 20-30% | D14: 5-10% | E14: Moderate-High | F14: Growth + some safety | G14: ₹10L: ₹6.5L Equity, ₹2.5L Debt, ₹1L Gold
A15: 40-50 Years | B15: 45-55% | C15: 35-45% | D15: 5-10% | E15: Moderate | F15: Balanced growth & preservation | G15: ₹10L: ₹5L Equity, ₹4L Debt, ₹1L Gold
A16: 50-60 Years | B16: 30-40% | C16: 50-60% | D16: 5-10% | E16: Conservative | F16: Capital preservation | G16: ₹10L: ₹3.5L Equity, ₹5.5L Debt, ₹1L Gold
A17: 60+ Years | B17: 20-30% | C17: 60-70% | D17: 5-10% | E17: Very Conservative | F17: Income + safety | G17: ₹10L: ₹2.5L Equity, ₹6.5L Debt, ₹1L Gold
A19: YOUR CURRENT ALLOCATION ANALYSIS
A20: Asset Class | B20: Your Amount (₹) | C20: Your % | D20: Recommended % | E20: Difference | F20: Action Needed
A21: Equity (MF + Stocks) | B21: =SUMIF('Investments'!C6:C24,"Equity MF",'Investments'!E6:E24)+SUMIF('Investments'!C6:C24,"Stocks",'Investments'!E6:E24) -> 0 | C21: =B7/SUM(B7:B14)*100% -> 0 | D21: 65% | E21: =B8-C8 -> 0 | F21: =IF(B8>C8,"REDUCE","INCREASE") -> 0
A22: Debt (MF + FD) | B22: =SUMIF('Investments'!C6:C24,"Debt MF",'Investments'!E6:E24)+SUMIF('Investments'!C6:C24,"FD",'Investments'!E6:E24) -> 0 | C22: =B8/SUM(B7:B14)*100% -> 0 | D22: 25% | E22: =B9-C9 -> 0 | F22: =IF(B9>C9,"REDUCE","INCREASE") -> 0
A23: Retirement (NPS) | B23: =SUMIF('Investments'!C6:C24,"NPS",'Investments'!E6:E24) -> 0 | C23: =B9/SUM(B7:B14)*100% -> 0 | D23: 5% | E23: =B10-C10 -> 0 | F23: =IF(B10>C10,"REDUCE","INCREASE") -> 0
A24: Safe (PPF, Gold) | B24: =SUMIF('Investments'!C6:C24,"PPF",'Investments'!E6:E24)+SUMIF('Investments'!C6:C24,"Gold/Silver",'Investments'!E6:E24) -> 0 | C24: =B10/SUM(B7:B14)*100% -> 0 | D24: 5% | E24: =B11-C11 -> 0 | F24: =IF(B11>C11,"REDUCE","INCREASE") -> 0
A26: DETAILED ALLOCATION BREAKDOWN
A27: Asset Class | B27: Invested Amount | C27: Current Value | D27: Return % | E27: Allocation %
A29: EQUITY INVESTMENTS (Growth Focus)
A30: Large Cap Funds | B30: =SUMIF('Investments'!A6:A24,"*Large*",'Investments'!D6:D24) -> 0 | C30: =SUMIF('Investments'!A6:A24,"*Large*",'Investments'!E6:E24) -> 0 | D30: =SUMIF('Investments'!A6:A24,"*Large*",'Investments'!G6:G24)% -> 0 | E30: =SUMIF('Investments'!A6:A24,"*Large*",'Investments'!E6:E24)/SUM('Investments'!E6:E24)*100% -> 0 | F30: 30-40%
A31: Mid Cap Funds | B31: 0 | C31: 0 | D31: 0% | E31: 0% | F31: 20-30%
A32: Small Cap Funds | B32: 0 | C32: 0 | D32: 0% | E32: 0% | F32: 10-20%
A33: Direct Stocks | B33: =SUMIF('Investments'!C6:C24,"Stocks",'Investments'!D6:D24) -> 0 | C33: =SUMIF('Investments'!C6:C24,"Stocks",'Investments'!E6:E24) -> 0 | D33: =SUMIF('Investments'!C6:C24,"Stocks",'Investments'!G6:G24)% -> 0 | E33: =SUMIF('Investments'!C6:C24,"Stocks",'Investments'!E6:E24)/SUM('Investments'!E6:E24)*100% -> 0 | F33: 0-20%
A34: ELSS/Tax Saving Funds | B34: 0 | C34: 0 | D34: 0% | E34: 0% | F34: 5-10%
A36: DEBT INVESTMENTS (Safety Focus)
A37: Debt Mutual Funds | B37: =SUMIF('Investments'!C6:C24,"Debt MF",'Investments'!D6:D24) -> 0 | C37: =SUMIF('Investments'!C6:C24,"Debt MF",'Investments'!E6:E24) -> 0 | D37: =AVERAGE(INDIRECT("'Investments'!G"&MATCH("Debt MF",'Investments'!C6:C24,0)))% -> 0 | E37: =SUMIF('Investments'!C6:C24,"Debt MF",'Investments'!E6:E24)/SUM('Investments'!E6:E24)*100% -> 0 | F37: 10-15%
A38: Bank Fixed Deposits | B38: =SUMIF('Investments'!C6:C24,"FD",'Investments'!D6:D24) -> 0 | C38: =SUMIF('Investments'!C6:C24,"FD",'Investments'!E6:E24) -> 0 | D38: =SUMIF('Investments'!C6:C24,"FD",'Investments'!G6:G24)% -> 0 | E38: =SUMIF('Investments'!C6:C24,"FD",'Investments'!E6:E24)/SUM('Investments'!E6:E24)*100% -> 0 | F38: 10-15%
A39: Bonds/Debentures | B39: 0 | C39: 0 | D39: 0% | E39: 0% | F39: 0-10%
A40: Liquid Funds | B40: 0 | C40: 0 | D40: 0% | E40: 0% | F40: 0-5% (Emergency)
A42: RETIREMENT & SAFE INVESTMENTS
A43: NPS (National Pension System) | B43: =SUMIF('Investments'!C6:C24,"NPS",'Investments'!D6:D24) -> 0 | C43: =SUMIF('Investments'!C6:C24,"NPS",'Investments'!E6:E24) -> 0 | D43: =SUMIF('Investments'!C6:C24,"NPS",'Investments'!G6:G24)% -> 0 | E43: =SUMIF('Investments'!C6:C24,"NPS",'Investments'!E6:E24)/SUM('Investments'!E6:E24)*100% -> 0 | F43: 10-20%
A44: PPF (Public Provident Fund) | B44: =SUMIF('Investments'!C6:C24,"PPF",'Investments'!D6:D24) -> 0 | C44: =SUMIF('Investments'!C6:C24,"PPF",'Investments'!E6:E24) -> 0 | D44: =SUMIF('Investments'!C6:C24,"PPF",'Investments'!G6:G24)% -> 0 | E44: =SUMIF('Investments'!C6:C24,"PPF",'Investments'!E6:E24)/SUM('Investments'!E6:E24)*100% -> 0 | F44: 0-10%
A45: Gold/Silver ETF | B45: =SUMIF('Investments'!C6:C24,"Gold/Silver",'Investments'!D6:D24) -> 0 | C45: =SUMIF('Investments'!C6:C24,"Gold/Silver",'Investments'!E6:E24) -> 0 | D45: =SUMIF('Investments'!C6:C24,"Gold/Silver",'Investments'!G6:G24)% -> 0 | E45: =SUMIF('Investments'!C6:C24,"Gold/Silver",'Investments'!E6:E24)/SUM('Investments'!E6:E24)*100% -> 0 | F45: 0-5%
A47: REBALANCING RECOMMENDATIONS
A48: Status | B48: Action | C48: Target Allocation | D48: Current Allocation | E48: Amount to | F48: When
A49: =IF(B7>C7,'Asset Allocation'!C8,"OK") -> 0 | B49: =IF(B7>C7,"REDUCE Equity","OK") -> 0 | C49: 65% | D49: =B7/SUM(B7:B14)*100% -> 0 | E49: =IF(B7>C7,B7-C7*SUM(B7:B14),0) -> 0 | F49: Quarterly
...

Sheet Tax Strategy
A1: INVESTMENT TAX OPTIMIZATION STRATEGY
A3: Maximize after-tax returns with smart investment choices.
A5: TAX TREATMENT OF INVESTMENTS (2025-26)
A6: Asset Type | B6: Short-term Capital Gains (Hold <1 yr) | C6: Long-term Capital Gains (Hold >1 yr) | D6: Dividend Tax | E6: Interest Tax
A7: Equity Mutual Funds | B7: As per income slab (15-45%) | C7: 10% (if >₹1L), else 0% | D7: Dividend exempt | E7: N/A
A8: Stocks (Listed) | B8: As per income slab (15-45%) | C8: 10% (if >₹1L), else 0% | D8: As per slab | E8: N/A
A9: Debt Mutual Funds | B9: As per income slab (15-45%) | C9: 20% with indexation benefit | D9: As per slab | E9: N/A
A10: Fixed Deposits (Bank) | B10: N/A | C10: N/A | D10: N/A | E10: As per income slab
A11: PPF | B11: N/A | C11: 100% EXEMPT | D11: N/A | E11: N/A
A12: NPS | B12: N/A | C12: Partial exempt (40%) | D12: N/A | E12: N/A
A13: Gold | B13: As per income slab | C13: 20% with indexation | D13: N/A | E13: N/A
A15: INVESTMENT TAX SAVING STRATEGIES (Section 80C)
A16: Strategy | B16: Investment | C16: Max Limit | D16: Tax Benefit | E16: Holding Period
A17: 1. Maximize 80C | B17: Invest in ELSS, PPF, Life Insurance | C17: ₹1,50,000 | D17: ₹45,000-67,500 (30-45% slab) | E17: ELSS: 3 yrs, PPF: 15 yrs
A18: 2. Add 80D (Insurance) | B18: Medical insurance for self, family | C18: ₹25,000-50,000 | D18: ₹7,500-22,500 | E18: Yearly premium
A19: 3. Long-term Holding | B19: Hold stocks/MF >1 year | C19: No limit | D19: Reduced capital gains tax | E19: LTCG: 10% only
A20: 4. Indexation Benefit | B20: Hold debt MF/gold >2 years | C20: No limit | D20: 20% + inflation adjustment | E20: 3-5 years minimum
A21: 5. Tax-Loss Harvesting | B21: Sell losing investments | C21: No limit | D21: Offset gains with losses | E21: Immediate
A23: ANNUAL TAX PLANNING CHECKLIST
A24: Task | B24: Deadline | C24: Tax Saved | D24: Status | E24: Notes
A25: Invest in ELSS/PPF (80C) | B25: March 31 | C25: ₹30,000-45,000 | D25: Plan early | E25: Max ₹1,50,000
A26: Medical Insurance 80D | B26: March 31 | C26: ₹5,000-15,000 | D26: Renew policies | E26: Max ₹25,000
A27: Review & Harvest Losses | B27: December | C27: ₹10,000-50,000 | D27: Sell underperformers | E27: Offset gains
A28: Rebalance for LTCG | B28: Ongoing | C28: Variable | D28: Hold >1 year | E28: Lower tax rate
A29: Track investment expenses | B29: Throughout year | C29: ₹2,000-5,000 | D29: Keep records | E29: Deduct costs
A31: TAX SCENARIO: ₹15 LPA EARNER
A33: SCENARIO 1: Without Tax Planning
A34: Income | B34: ₹15,00,000
A35: No deductions claimed
A36: Taxable Income | B36: ₹15,00,000
A37: Income Tax (at 30% slab) | B37: ₹4,50,000
A38: Health Cess (4%) | B38: ₹18,000
A39: TOTAL TAX | B39: ₹4,68,000 | D39: Wasted opportunity!
A41: SCENARIO 2: With Smart Tax Planning
A42: Income | B42: ₹15,00,000
A43: 80C Deduction (ELSS) | B43: -₹1,50,000 | C43: Max limit
A44: 80D (Medical Insurance) | B44: -₹25,000 | C44: Max limit
A45: Home Loan Interest 24(b) | B45: -₹2,00,000 | C45: Max limit
A46: Taxable Income | B46: ₹11,25,000 | D46: Reduced!
A47: Income Tax (at 30% slab) | B47: ₹3,37,500
...

Sheet Goals Tracker
A1: INVESTMENT GOALS & PROGRESS TRACKER
A3: Track progress toward your financial goals with target amounts and timelines.
A5: FINANCIAL GOALS PLANNING
A6: Goal Name | B6: Target Amount (₹) | C6: Target Date | D6: Years Away | E6: Current Progress (₹) | F6: Progress % | G6: Status
A7: Retirement Fund | B7: 5000000 | C7: 2045-01-02 | D7: =YEAR(D8)-YEAR(TODAY()) -> 0 | E7: =SUMIF('Investments'!C6:C24,"NPS",'Investments'!E6:E24) -> 0 | F7: =E8/B8*100% -> 0 | G7: =IF(F8>=50%,"On Track","Behind") -> 0
A8: Home Down Payment | B8: 2000000 | C8: 2028-01-02 | D8: =YEAR(D9)-YEAR(TODAY()) -> 0 | E8: =SUMIF('Investments'!C6:C24,"Stocks",'Investments'!E6:E24)*0.30 -> 0 | F8: =E9/B9*100% -> 0 | G8: =IF(F9>=50%,"On Track","Behind") -> 0
A9: Child Education Fund | B9: 3000000 | C9: 2038-01-02 | D9: =YEAR(D10)-YEAR(TODAY()) -> 0 | E9: =SUMIF('Investments'!C6:C24,"Equity MF",'Investments'!E6:E24)*0.40 -> 0 | F9: =E10/B10*100% -> 0 | G9: =IF(F10>=50%,"On Track","Behind") -> 0
A10: Vacation/Travel | B10: 500000 | C10: 2026-06-02 | D10: =YEAR(D11)-YEAR(TODAY()) -> 0 | E10: =SUMIF('Investments'!C6:C24,"FD",'Investments'!E6:E24)*0.20 -> 0 | F10: =E11/B11*100% -> 0 | G10: =IF(F11>=50%,"On Track","Behind") -> 0
A11: Emergency Fund (6 months) | B11: 750000 | C11: 2026-03-02 | D11: =YEAR(D12)-YEAR(TODAY()) -> 0 | E11: =SUMIF('Investments'!C6:C24,"Debt MF",'Investments'!E6:E24) -> 0 | F11: =E12/B12*100% -> 0 | G11: =IF(F12>=100%,"✓ Complete","In Progress") -> 0
A12: Vehicle Purchase | B12: 1200000 | C12: 2027-01-02 | D12: =YEAR(D13)-YEAR(TODAY()) -> 0 | E12: =SUMIF('Investments'!C6:C24,"FD",'Investments'!E6:E24)*0.40 -> 0 | F12: =E13/B13*100% -> 0 | G12: =IF(F13>=50%,"On Track","Behind") -> 0
A14: MONTHLY SAVINGS REQUIRED
A15: Goal | B15: Target Amount | C15: Years Left | D15: Monthly Needed (7% return) | E15: Current Monthly SIP | F15: Gap
A16: Retirement Fund | B16: =B8 -> 0 | C16: =C8 -> 0 | D16: =B8/(C8*12*1.07) -> 0 | E16: 50000 | F16: =MAX(0,((B8/(C8*12*1.07))-D16)) -> 0
A17: Home Down Payment | B17: =B9 -> 0 | C17: =C9 -> 0 | D17: =B9/(C9*12*1.07) -> 0 | E17: 30000 | F17: =MAX(0,((B9/(C9*12*1.07))-D17)) -> 0
A18: Child Education Fund | B18: =B10 -> 0 | C18: =C10 -> 0 | D18: =B10/(C10*12*1.07) -> 0 | E18: 25000 | F18: =MAX(0,((B10/(C10*12*1.07))-D18)) -> 0
A19: Vacation/Travel | B19: =B11 -> 0 | C19: =C11 -> 0 | D19: =B11/(C11*12*1.07) -> 0 | E19: 10000 | F19: =MAX(0,((B11/(C11*12*1.07))-D19)) -> 0
A20: Emergency Fund | B20: =B12 -> 0 | C20: =C12 -> 0 | D20: =B12/(C12*12*1.07) -> 0 | E20: 15000 | F20: =MAX(0,((B12/(C12*12*1.07))-D20)) -> 0
A21: Vehicle Purchase | B21: =B13 -> 0 | C21: =C13 -> 0 | D21: =B13/(C13*12*1.07) -> 0 | E21: 20000 | F21: =MAX(0,((B13/(C13*12*1.07))-D21)) -> 0
A23: MILESTONE CHECKLIST
A24: Milestone | B24: Target Completion | C24: Completed | D24: Notes
A25: First ₹1 Lakh Portfolio | B25: By 2026-06-02 | C25: =IF(SUM('Investments'!E6:E24)>=100000,"✓ YES","In Progress") -> 0 | D25: Building foundation
A26: First ₹5 Lakh Portfolio | B26: By 2027-01-02 | C26: =IF(SUM('Investments'!E6:E24)>=500000,"✓ YES","In Progress") -> 0 | D26: Growing wealth
A27: First ₹10 Lakh Portfolio | B27: By 2028-01-02 | C27: =IF(SUM('Investments'!E6:E24)>=1000000,"✓ YES","In Progress") -> 0 | D27: Significant progress
A28: 10 Different Investments | B28: By 2026-06-02 | C28: =IF(COUNTA('Investments'!A6:A24)>=10,"✓ YES","In Progress") -> 0 | D28: Diversification
A29: 20% CAGR Average | B29: By 2027-01-02 | C29: =IF(AVERAGE('Return Calculator'!B12)>=20,"✓ YES","In Progress") -> 0 | D29: Strong returns
